Workbook
Name TBL_PLANES: Planes!$A$5:$G$14
Name TBL_CLIENTES: Clientes!$A$5:$G$30
Name TBL_SUB: Suscripciones!$A$5:$M$30
Name TBL_PAGOS: Pagos!$A$5:$I$50
Name TBL_EC: EstadoCuenta!$A$5:$O$30
Name TBL_REWARDS: Rewards!$A$5:$G$22

Sheet Dashboard
A1: 📊 DASHBOARD — SUSCRIPCIONES & REWARDS
A2: Actualizado al abrir · TODAY() recalcula automáticamente · MateAI
A4: 💰 INGRESOS
A5: KPI | B5: Valor | C5: Detalle
A6: MRR (Ingreso recurrente mensual) | B6: =SUMPRODUCT((Suscripciones!F5:F30="Mensual")*(Suscripciones!J5:J30="Activa")*Suscripciones!G5:G30)+SUMPRODUCT((Suscripciones!F5:F30="Anual")*(Suscripciones!J5:J30="Activa")*Suscripciones!G5:G30)/12 | C6: Mensuales activos + (Anuales activos / 12)
A7: ARR (Ingreso anualizado) | B7: =B6*12 | C7: MRR × 12
A8: Cobrado este mes | B8: =SUMIFS(Pagos!F:F,Pagos!B:B,">="&DATE(YEAR(TODAY()),MONTH(TODAY()),1),Pagos!B:B,"<"&DATE(YEAR(TODAY()),MONTH(TODAY())+1,1)) | C8: Suma de pagos del mes actual
A9: Cobrado total histórico | B9: =SUM(Pagos!F:F) | C9: Suma de todos los pagos registrados
A10: Saldo pendiente total | B10: =SUMIF(EstadoCuenta!L5:L30,">0") | C10: Suma de saldos positivos (clientes que deben)
A12: 📌 SUSCRIPCIONES
A13: KPI | B13: Valor | C13: Detalle
A14: Suscripciones activas | B14: =COUNTIF(Suscripciones!J5:J30,"Activa") | C14: Estado = Activa
A15: Suscripciones pausadas | B15: =COUNTIF(Suscripciones!J5:J30,"Pausada") | C15: Estado = Pausada
A16: Suscripciones canceladas | B16: =COUNTIF(Suscripciones!J5:J30,"Cancelada") | C16: Estado = Cancelada
A17: Clientes al día | B17: =COUNTIF(EstadoCuenta!O5:O30,"Al día") | C17: Sin saldo pendiente
A18: Clientes por cobrar (≤7 días) | B18: =COUNTIF(EstadoCuenta!O5:O30,"Por cobrar") | C18: Próximo cobro en los próximos 7 días
A19: Clientes en mora | B19: =COUNTIF(EstadoCuenta!O5:O30,"En mora") | C19: Saldo pendiente y fecha de cobro vencida
A20: Plan más popular | B20: =IFERROR(INDEX(Suscripciones!E5:E30,MATCH(MAX(COUNTIF(Suscripciones!E5:E30,Suscripciones!E5:E30)),COUNTIF(Suscripciones!E5:E30,Suscripciones!E5:E30),0)),"") | C20: Plan con más suscripciones
A22: 🎁 REWARDS
A23: KPI | B23: Valor | C23: Detalle
A24: Total puntos otorgados | B24: =SUMPRODUCT((EstadoCuenta!A5:A30<>"")*EstadoCuenta!J5:J30*IFERROR(VLOOKUP(EstadoCuenta!C5:C30,Planes!$B$5:$E$14,4,FALSE),0)) | C24: Cuotas pagadas × puntos por ciclo del plan
A25: Puntos gastados (canjeados) | B25: =SUMIF(Canjes!J5:J30,"Canjeado",Canjes!H5:H30) | C25: Suma de costo en puntos de canjes confirmados
A26: Saldo de puntos disponibles | B26: =B24-B25 | C26: Otorgados − gastados
A27: Total canjes (todos) | B27: =COUNTA(Canjes!A5:A30) | C27: Filas registradas en Canjes
A28: Canjes pendientes | B28: =COUNTIF(Canjes!J5:J30,"Pendiente") | C28: Estado = Pendiente (acción requerida)
A29: Reward más canjeado | B29: =IFERROR(INDEX(Canjes!G5:G30,MATCH(MAX(COUNTIF(Canjes!G5:G30,Canjes!G5:G30)),COUNTIF(Canjes!G5:G30,Canjes!G5:G30),0)),"") | C29: Reward con más canjes
A32: 📌 Cómo usar el sistema
A33: 1) Edita primero PLANES y REWARDS (catálogos maestros).
A34: 2) Da de alta CLIENTES → ID Cliente, nombre, contacto.
A35: 3) Crea cada SUSCRIPCIÓN: ID Cliente + ID Plan + Fecha inicio + Día de cobro. El Plan, Precio y Periodicidad se autocompletan.
A36: 4) Cada vez que cobres, registra una fila en PAGOS: Fecha, ID Sub y Monto. Cliente y Plan se autocompletan.
A37: 5) ESTADO DE CUENTA muestra automáticamente: cuotas esperadas, total facturado, total pagado, saldo, próximo cobro y mora.
A38: 6) Revisa ALERTAS para ver de un vistazo quién debe pagar pronto y quién está atrasado.
A39: 7) Registra rewards canjeados en CANJES → calcula automáticamente el saldo de puntos disponibles.
A40: 8) DASHBOARD recalcula MRR, ARR, mora y puntos al abrir el archivo.
A42: 🎨 Convención de color: AZUL = entrada manual · NEGRO = fórmula automática (no editar)
A43: 🔄 Las celdas con TODAY() se recalculan al abrir Excel/Google Sheets.

Sheet Alertas
A1: 🚨 ALERTAS DE COBRO
A2: Suscripciones por cobrar próximamente y clientes en mora · auto desde EstadoCuenta
A4: ▼ POR COBRAR (próximos 7 días)
A5: Estado | B5: ID Sub | C5: Cliente | D5: Plan | E5: Precio | F5: Próx. cobro | G5: Días para cobro | H5: Saldo | I5: Método pago
A6: =IFERROR(INDEX(EstadoCuenta!$O$5:$O$30,IFERROR(SMALL(IF(EstadoCuenta!$O$5:$O$30="Por cobrar",ROW(EstadoCuenta!$O$5:$O$30)),1),"")-4),"") | B6: =IFERROR(INDEX(EstadoCuenta!$A$5:$A$30,IFERROR(SMALL(IF(EstadoCuenta!$O$5:$O$30="Por cobrar",ROW(EstadoCuenta!$O$5:$O$30)),1),"")-4),"") | C6: =IFERROR(INDEX(EstadoCuenta!$B$5:$B$30,IFERROR(SMALL(IF(EstadoCuenta!$O$5:$O$30="Por cobrar",ROW(EstadoCuenta!$O$5:$O$30)),1),"")-4),"") | D6: =IFERROR(INDEX(EstadoCuenta!$C$5:$C$30,IFERROR(SMALL(IF(EstadoCuenta!$O$5:$O$30="Por cobrar",ROW(EstadoCuenta!$O$5:$O$30)),1),"")-4),"") | E6: =IFERROR(INDEX(EstadoCuenta!$E$5:$E$30,IFERROR(SMALL(IF(EstadoCuenta!$O$5:$O$30="Por cobrar",ROW(EstadoCuenta!$O$5:$O$30)),1),"")-4),"") | F6: =IFERROR(INDEX(EstadoCuenta!$M$5:$M$30,IFERROR(SMALL(IF(EstadoCuenta!$O$5:$O$30="Por cobrar",ROW(EstadoCuenta!$O$5:$O$30)),1),"")-4),"") | G6: =IFERROR(INDEX(EstadoCuenta!$N$5:$N$30,IFERROR(SMALL(IF(EstadoCuenta!$O$5:$O$30="Por cobrar",ROW(EstadoCuenta!$O$5:$O$30)),1),"")-4),"") | H6: =IFERROR(INDEX(EstadoCuenta!$L$5:$L$30,IFERROR(SMALL(IF(EstadoCuenta!$O$5:$O$30="Por cobrar",ROW(EstadoCuenta!$O$5:$O$30)),1),"")-4),"") | I6: =IFERROR(VLOOKUP(B6,Suscripciones!$A$5:$L$30,12,FALSE),"")
A7: =IFERROR(INDEX(EstadoCuenta!$O$5:$O$30,IFERROR(SMALL(IF(EstadoCuenta!$O$5:$O$30="Por cobrar",ROW(EstadoCuenta!$O$5:$O$30)),2),"")-4),"") | B7: =IFERROR(INDEX(EstadoCuenta!$A$5:$A$30,IFERROR(SMALL(IF(EstadoCuenta!$O$5:$O$30="Por cobrar",ROW(EstadoCuenta!$O$5:$O$30)),2),"")-4),"") | C7: =IFERROR(INDEX(EstadoCuenta!$B$5:$B$30,IFERROR(SMALL(IF(EstadoCuenta!$O$5:$O$30="Por cobrar",ROW(EstadoCuenta!$O$5:$O$30)),2),"")-4),"") | D7: =IFERROR(INDEX(EstadoCuenta!$C$5:$C$30,IFERROR(SMALL(IF(EstadoCuenta!$O$5:$O$30="Por cobrar",ROW(EstadoCuenta!$O$5:$O$30)),2),"")-4),"") | E7: =IFERROR(INDEX(EstadoCuenta!$E$5:$E$30,IFERROR(SMALL(IF(EstadoCuenta!$O$5:$O$30="Por cobrar",ROW(EstadoCuenta!$O$5:$O$30)),2),"")-4),"") | F7: =IFERROR(INDEX(EstadoCuenta!$M$5:$M$30,IFERROR(SMALL(IF(EstadoCuenta!$O$5:$O$30="Por cobrar",ROW(EstadoCuenta!$O$5:$O$30)),2),"")-4),"") | G7: =IFERROR(INDEX(EstadoCuenta!$N$5:$N$30,IFERROR(SMALL(IF(EstadoCuenta!$O$5:$O$30="Por cobrar",ROW(EstadoCuenta!$O$5:$O$30)),2),"")-4),"") | H7: =IFERROR(INDEX(EstadoCuenta!$L$5:$L$30,IFERROR(SMALL(IF(EstadoCuenta!$O$5:$O$30="Por cobrar",ROW(EstadoCuenta!$O$5:$O$30)),2),"")-4),"") | I7: =IFERROR(VLOOKUP(B7,Suscripciones!$A$5:$L$30,12,FALSE),"")
A8: =IFERROR(INDEX(EstadoCuenta!$O$5:$O$30,IFERROR(SMALL(IF(EstadoCuenta!$O$5:$O$30="Por cobrar",ROW(EstadoCuenta!$O$5:$O$30)),3),"")-4),"") | B8: =IFERROR(INDEX(EstadoCuenta!$A$5:$A$30,IFERROR(SMALL(IF(EstadoCuenta!$O$5:$O$30="Por cobrar",ROW(EstadoCuenta!$O$5:$O$30)),3),"")-4),"") | C8: =IFERROR(INDEX(EstadoCuenta!$B$5:$B$30,IFERROR(SMALL(IF(EstadoCuenta!$O$5:$O$30="Por cobrar",ROW(EstadoCuenta!$O$5:$O$30)),3),"")-4),"") | D8: =IFERROR(INDEX(EstadoCuenta!$C$5:$C$30,IFERROR(SMALL(IF(EstadoCuenta!$O$5:$O$30="Por cobrar",ROW(EstadoCuenta!$O$5:$O$30)),3),"")-4),"") | E8: =IFERROR(INDEX(EstadoCuenta!$E$5:$E$30,IFERROR(SMALL(IF(EstadoCuenta!$O$5:$O$30="Por cobrar",ROW(EstadoCuenta!$O$5:$O$30)),3),"")-4),"") | F8: =IFERROR(INDEX(EstadoCuenta!$M$5:$M$30,IFERROR(SMALL(IF(EstadoCuenta!$O$5:$O$30="Por cobrar",ROW(EstadoCuenta!$O$5:$O$30)),3),"")-4),"") | G8: =IFERROR(INDEX(EstadoCuenta!$N$5:$N$30,IFERROR(SMALL(IF(EstadoCuenta!$O$5:$O$30="Por cobrar",ROW(EstadoCuenta!$O$5:$O$30)),3),"")-4),"") | H8: =IFERROR(INDEX(EstadoCuenta!$L$5:$L$30,IFERROR(SMALL(IF(EstadoCuenta!$O$5:$O$30="Por cobrar",ROW(EstadoCuenta!$O$5:$O$30)),3),"")-4),"") | I8: =IFERROR(VLOOKUP(B8,Suscripciones!$A$5:$L$30,12,FALSE),"")
A9: =IFERROR(INDEX(EstadoCuenta!$O$5:$O$30,IFERROR(SMALL(IF(EstadoCuenta!$O$5:$O$30="Por cobrar",ROW(EstadoCuenta!$O$5:$O$30)),4),"")-4),"") | B9: =IFERROR(INDEX(EstadoCuenta!$A$5:$A$30,IFERROR(SMALL(IF(EstadoCuenta!$O$5:$O$30="Por cobrar",ROW(EstadoCuenta!$O$5:$O$30)),4),"")-4),"") | C9: =IFERROR(INDEX(EstadoCuenta!$B$5:$B$30,IFERROR(SMALL(IF(EstadoCuenta!$O$5:$O$30="Por cobrar",ROW(EstadoCuenta!$O$5:$O$30)),4),"")-4),"") | D9: =IFERROR(INDEX(EstadoCuenta!$C$5:$C$30,IFERROR(SMALL(IF(EstadoCuenta!$O$5:$O$30="Por cobrar",ROW(EstadoCuenta!$O$5:$O$30)),4),"")-4),"") | E9: =IFERROR(INDEX(EstadoCuenta!$E$5:$E$30,IFERROR(SMALL(IF(EstadoCuenta!$O$5:$O$30="Por cobrar",ROW(EstadoCuenta!$O$5:$O$30)),4),"")-4),"") | F9: =IFERROR(INDEX(EstadoCuenta!$M$5:$M$30,IFERROR(SMALL(IF(EstadoCuenta!$O$5:$O$30="Por cobrar",ROW(EstadoCuenta!$O$5:$O$30)),4),"")-4),"") | G9: =IFERROR(INDEX(EstadoCuenta!$N$5:$N$30,IFERROR(SMALL(IF(EstadoCuenta!$O$5:$O$30="Por cobrar",ROW(EstadoCuenta!$O$5:$O$30)),4),"")-4),"") | H9: =IFERROR(INDEX(EstadoCuenta!$L$5:$L$30,IFERROR(SMALL(IF(EstadoCuenta!$O$5:$O$30="Por cobrar",ROW(EstadoCuenta!$O$5:$O$30)),4),"")-4),"") | I9: =IFERROR(VLOOKUP(B9,Suscripciones!$A$5:$L$30,12,FALSE),"")
A10: =IFERROR(INDEX(EstadoCuenta!$O$5:$O$30,IFERROR(SMALL(IF(EstadoCuenta!$O$5:$O$30="Por cobrar",ROW(EstadoCuenta!$O$5:$O$30)),5),"")-4),"") | B10: =IFERROR(INDEX(EstadoCuenta!$A$5:$A$30,IFERROR(SMALL(IF(EstadoCuenta!$O$5:$O$30="Por cobrar",ROW(EstadoCuenta!$O$5:$O$30)),5),"")-4),"") | C10: =IFERROR(INDEX(EstadoCuenta!$B$5:$B$30,IFERROR(SMALL(IF(EstadoCuenta!$O$5:$O$30="Por cobrar",ROW(EstadoCuenta!$O$5:$O$30)),5),"")-4),"") | D10: =IFERROR(INDEX(EstadoCuenta!$C$5:$C$30,IFERROR(SMALL(IF(EstadoCuenta!$O$5:$O$30="Por cobrar",ROW(EstadoCuenta!$O$5:$O$30)),5),"")-4),"") | E10: =IFERROR(INDEX(EstadoCuenta!$E$5:$E$30,IFERROR(SMALL(IF(EstadoCuenta!$O$5:$O$30="Por cobrar",ROW(EstadoCuenta!$O$5:$O$30)),5),"")-4),"") | F10: =IFERROR(INDEX(EstadoCuenta!$M$5:$M$30,IFERROR(SMALL(IF(EstadoCuenta!$O$5:$O$30="Por cobrar",ROW(EstadoCuenta!$O$5:$O$30)),5),"")-4),"") | G10: =IFERROR(INDEX(EstadoCuenta!$N$5:$N$30,IFERROR(SMALL(IF(EstadoCuenta!$O$5:$O$30="Por cobrar",ROW(EstadoCuenta!$O$5:$O$30)),5),"")-4),"") | H10: =IFERROR(INDEX(EstadoCuenta!$L$5:$L$30,IFERROR(SMALL(IF(EstadoCuenta!$O$5:$O$30="Por cobrar",ROW(EstadoCuenta!$O$5:$O$30)),5),"")-4),"") | I10: =IFERROR(VLOOKUP(B10,Suscripciones!$A$5:$L$30,12,FALSE),"")
A11: =IFERROR(INDEX(EstadoCuenta!$O$5:$O$30,IFERROR(SMALL(IF(EstadoCuenta!$O$5:$O$30="Por cobrar",ROW(EstadoCuenta!$O$5:$O$30)),6),"")-4),"") | B11: =IFERROR(INDEX(EstadoCuenta!$A$5:$A$30,IFERROR(SMALL(IF(EstadoCuenta!$O$5:$O$30="Por cobrar",ROW(EstadoCuenta!$O$5:$O$30)),6),"")-4),"") | C11: =IFERROR(INDEX(EstadoCuenta!$B$5:$B$30,IFERROR(SMALL(IF(EstadoCuenta!$O$5:$O$30="Por cobrar",ROW(EstadoCuenta!$O$5:$O$30)),6),"")-4),"") | D11: =IFERROR(INDEX(EstadoCuenta!$C$5:$C$30,IFERROR(SMALL(IF(EstadoCuenta!$O$5:$O$30="Por cobrar",ROW(EstadoCuenta!$O$5:$O$30)),6),"")-4),"") | E11: =IFERROR(INDEX(EstadoCuenta!$E$5:$E$30,IFERROR(SMALL(IF(EstadoCuenta!$O$5:$O$30="Por cobrar",ROW(EstadoCuenta!$O$5:$O$30)),6),"")-4),"") | F11: =IFERROR(INDEX(EstadoCuenta!$M$5:$M$30,IFERROR(SMALL(IF(EstadoCuenta!$O$5:$O$30="Por cobrar",ROW(EstadoCuenta!$O$5:$O$30)),6),"")-4),"") | G11: =IFERROR(INDEX(EstadoCuenta!$N$5:$N$30,IFERROR(SMALL(IF(EstadoCuenta!$O$5:$O$30="Por cobrar",ROW(EstadoCuenta!$O$5:$O$30)),6),"")-4),"") | H11: =IFERROR(INDEX(EstadoCuenta!$L$5:$L$30,IFERROR(SMALL(IF(EstadoCuenta!$O$5:$O$30="Por cobrar",ROW(EstadoCuenta!$O$5:$O$30)),6),"")-4),"") | I11: =IFERROR(VLOOKUP(B11,Suscripciones!$A$5:$L$30,12,FALSE),"")
A12: =IFERROR(INDEX(EstadoCuenta!$O$5:$O$30,IFERROR(SMALL(IF(EstadoCuenta!$O$5:$O$30="Por cobrar",ROW(EstadoCuenta!$O$5:$O$30)),7),"")-4),"") | B12: =IFERROR(INDEX(EstadoCuenta!$A$5:$A$30,IFERROR(SMALL(IF(EstadoCuenta!$O$5:$O$30="Por cobrar",ROW(EstadoCuenta!$O$5:$O$30)),7),"")-4),"") | C12: =IFERROR(INDEX(EstadoCuenta!$B$5:$B$30,IFERROR(SMALL(IF(EstadoCuenta!$O$5:$O$30="Por cobrar",ROW(EstadoCuenta!$O$5:$O$30)),7),"")-4),"") | D12: =IFERROR(INDEX(EstadoCuenta!$C$5:$C$30,IFERROR(SMALL(IF(EstadoCuenta!$O$5:$O$30="Por cobrar",ROW(EstadoCuenta!$O$5:$O$30)),7),"")-4),"") | E12: =IFERROR(INDEX(EstadoCuenta!$E$5:$E$30,IFERROR(SMALL(IF(EstadoCuenta!$O$5:$O$30="Por cobrar",ROW(EstadoCuenta!$O$5:$O$30)),7),"")-4),"") | F12: =IFERROR(INDEX(EstadoCuenta!$M$5:$M$30,IFERROR(SMALL(IF(EstadoCuenta!$O$5:$O$30="Por cobrar",ROW(EstadoCuenta!$O$5:$O$30)),7),"")-4),"") | G12: =IFERROR(INDEX(EstadoCuenta!$N$5:$N$30,IFERROR(SMALL(IF(EstadoCuenta!$O$5:$O$30="Por cobrar",ROW(EstadoCuenta!$O$5:$O$30)),7),"")-4),"") | H12: =IFERROR(INDEX(EstadoCuenta!$L$5:$L$30,IFERROR(SMALL(IF(EstadoCuenta!$O$5:$O$30="Por cobrar",ROW(EstadoCuenta!$O$5:$O$30)),7),"")-4),"") | I12: =IFERROR(VLOOKUP(B12,Suscripciones!$A$5:$L$30,12,FALSE),"")
A13: =IFERROR(INDEX(EstadoCuenta!$O$5:$O$30,IFERROR(SMALL(IF(EstadoCuenta!$O$5:$O$30="Por cobrar",ROW(EstadoCuenta!$O$5:$O$30)),8),"")-4),"") | B13: =IFERROR(INDEX(EstadoCuenta!$A$5:$A$30,IFERROR(SMALL(IF(EstadoCuenta!$O$5:$O$30="Por cobrar",ROW(EstadoCuenta!$O$5:$O$30)),8),"")-4),"") | C13: =IFERROR(INDEX(EstadoCuenta!$B$5:$B$30,IFERROR(SMALL(IF(EstadoCuenta!$O$5:$O$30="Por cobrar",ROW(EstadoCuenta!$O$5:$O$30)),8),"")-4),"") | D13: =IFERROR(INDEX(EstadoCuenta!$C$5:$C$30,IFERROR(SMALL(IF(EstadoCuenta!$O$5:$O$30="Por cobrar",ROW(EstadoCuenta!$O$5:$O$30)),8),"")-4),"") | E13: =IFERROR(INDEX(EstadoCuenta!$E$5:$E$30,IFERROR(SMALL(IF(EstadoCuenta!$O$5:$O$30="Por cobrar",ROW(EstadoCuenta!$O$5:$O$30)),8),"")-4),"") | F13: =IFERROR(INDEX(EstadoCuenta!$M$5:$M$30,IFERROR(SMALL(IF(EstadoCuenta!$O$5:$O$30="Por cobrar",ROW(EstadoCuenta!$O$5:$O$30)),8),"")-4),"") | G13: =IFERROR(INDEX(EstadoCuenta!$N$5:$N$30,IFERROR(SMALL(IF(EstadoCuenta!$O$5:$O$30="Por cobrar",ROW(EstadoCuenta!$O$5:$O$30)),8),"")-4),"") | H13: =IFERROR(INDEX(EstadoCuenta!$L$5:$L$30,IFERROR(SMALL(IF(EstadoCuenta!$O$5:$O$30="Por cobrar",ROW(EstadoCuenta!$O$5:$O$30)),8),"")-4),"") | I13: =IFERROR(VLOOKUP(B13,Suscripciones!$A$5:$L$30,12,FALSE),"")
A14: =IFERROR(INDEX(EstadoCuenta!$O$5:$O$30,IFERROR(SMALL(IF(EstadoCuenta!$O$5:$O$30="Por cobrar",ROW(EstadoCuenta!$O$5:$O$30)),9),"")-4),"") | B14: =IFERROR(INDEX(EstadoCuenta!$A$5:$A$30,IFERROR(SMALL(IF(EstadoCuenta!$O$5:$O$30="Por cobrar",ROW(EstadoCuenta!$O$5:$O$30)),9),"")-4),"") | C14: =IFERROR(INDEX(EstadoCuenta!$B$5:$B$30,IFERROR(SMALL(IF(EstadoCuenta!$O$5:$O$30="Por cobrar",ROW(EstadoCuenta!$O$5:$O$30)),9),"")-4),"") | D14: =IFERROR(INDEX(EstadoCuenta!$C$5:$C$30,IFERROR(SMALL(IF(EstadoCuenta!$O$5:$O$30="Por cobrar",ROW(EstadoCuenta!$O$5:$O$30)),9),"")-4),"") | E14: =IFERROR(INDEX(EstadoCuenta!$E$5:$E$30,IFERROR(SMALL(IF(EstadoCuenta!$O$5:$O$30="Por cobrar",ROW(EstadoCuenta!$O$5:$O$30)),9),"")-4),"") | F14: =IFERROR(INDEX(EstadoCuenta!$M$5:$M$30,IFERROR(SMALL(IF(EstadoCuenta!$O$5:$O$30="Por cobrar",ROW(EstadoCuenta!$O$5:$O$30)),9),"")-4),"") | G14: =IFERROR(INDEX(EstadoCuenta!$N$5:$N$30,IFERROR(SMALL(IF(EstadoCuenta!$O$5:$O$30="Por cobrar",ROW(EstadoCuenta!$O$5:$O$30)),9),"")-4),"") | H14: =IFERROR(INDEX(EstadoCuenta!$L$5:$L$30,IFERROR(SMALL(IF(EstadoCuenta!$O$5:$O$30="Por cobrar",ROW(EstadoCuenta!$O$5:$O$30)),9),"")-4),"") | I14: =IFERROR(VLOOKUP(B14,Suscripciones!$A$5:$L$30,12,FALSE),"")
A15: =IFERROR(INDEX(EstadoCuenta!$O$5:$O$30,IFERROR(SMALL(IF(EstadoCuenta!$O$5:$O$30="Por cobrar",ROW(EstadoCuenta!$O$5:$O$30)),10),"")-4),"") | B15: =IFERROR(INDEX(EstadoCuenta!$A$5:$A$30,IFERROR(SMALL(IF(EstadoCuenta!$O$5:$O$30="Por cobrar",ROW(EstadoCuenta!$O$5:$O$30)),10),"")-4),"") | C15: =IFERROR(INDEX(EstadoCuenta!$B$5:$B$30,IFERROR(SMALL(IF(EstadoCuenta!$O$5:$O$30="Por cobrar",ROW(EstadoCuenta!$O$5:$O$30)),10),"")-4),"") | D15: =IFERROR(INDEX(EstadoCuenta!$C$5:$C$30,IFERROR(SMALL(IF(EstadoCuenta!$O$5:$O$30="Por cobrar",ROW(EstadoCuenta!$O$5:$O$30)),10),"")-4),"") | E15: =IFERROR(INDEX(EstadoCuenta!$E$5:$E$30,IFERROR(SMALL(IF(EstadoCuenta!$O$5:$O$30="Por cobrar",ROW(EstadoCuenta!$O$5:$O$30)),10),"")-4),"") | F15: =IFERROR(INDEX(EstadoCuenta!$M$5:$M$30,IFERROR(SMALL(IF(EstadoCuenta!$O$5:$O$30="Por cobrar",ROW(EstadoCuenta!$O$5:$O$30)),10),"")-4),"") | G15: =IFERROR(INDEX(EstadoCuenta!$N$5:$N$30,IFERROR(SMALL(IF(EstadoCuenta!$O$5:$O$30="Por cobrar",ROW(EstadoCuenta!$O$5:$O$30)),10),"")-4),"") | H15: =IFERROR(INDEX(EstadoCuenta!$L$5:$L$30,IFERROR(SMALL(IF(EstadoCuenta!$O$5:$O$30="Por cobrar",ROW(EstadoCuenta!$O$5:$O$30)),10),"")-4),"") | I15: =IFERROR(VLOOKUP(B15,Suscripciones!$A$5:$L$30,12,FALSE),"")
A16: =IFERROR(INDEX(EstadoCuenta!$O$5:$O$30,IFERROR(SMALL(IF(EstadoCuenta!$O$5:$O$30="Por cobrar",ROW(EstadoCuenta!$O$5:$O$30)),11),"")-4),"") | B16: =IFERROR(INDEX(EstadoCuenta!$A$5:$A$30,IFERROR(SMALL(IF(EstadoCuenta!$O$5:$O$30="Por cobrar",ROW(EstadoCuenta!$O$5:$O$30)),11),"")-4),"") | C16: =IFERROR(INDEX(EstadoCuenta!$B$5:$B$30,IFERROR(SMALL(IF(EstadoCuenta!$O$5:$O$30="Por cobrar",ROW(EstadoCuenta!$O$5:$O$30)),11),"")-4),"") | D16: =IFERROR(INDEX(EstadoCuenta!$C$5:$C$30,IFERROR(SMALL(IF(EstadoCuenta!$O$5:$O$30="Por cobrar",ROW(EstadoCuenta!$O$5:$O$30)),11),"")-4),"") | E16: =IFERROR(INDEX(EstadoCuenta!$E$5:$E$30,IFERROR(SMALL(IF(EstadoCuenta!$O$5:$O$30="Por cobrar",ROW(EstadoCuenta!$O$5:$O$30)),11),"")-4),"") | F16: =IFERROR(INDEX(EstadoCuenta!$M$5:$M$30,IFERROR(SMALL(IF(EstadoCuenta!$O$5:$O$30="Por cobrar",ROW(EstadoCuenta!$O$5:$O$30)),11),"")-4),"") | G16: =IFERROR(INDEX(EstadoCuenta!$N$5:$N$30,IFERROR(SMALL(IF(EstadoCuenta!$O$5:$O$30="Por cobrar",ROW(EstadoCuenta!$O$5:$O$30)),11),"")-4),"") | H16: =IFERROR(INDEX(EstadoCuenta!$L$5:$L$30,IFERROR(SMALL(IF(EstadoCuenta!$O$5:$O$30="Por cobrar",ROW(EstadoCuenta!$O$5:$O$30)),11),"")-4),"") | I16: =IFERROR(VLOOKUP(B16,Suscripciones!$A$5:$L$30,12,FALSE),"")
A17: =IFERROR(INDEX(EstadoCuenta!$O$5:$O$30,IFERROR(SMALL(IF(EstadoCuenta!$O$5:$O$30="Por cobrar",ROW(EstadoCuenta!$O$5:$O$30)),12),"")-4),"") | B17: =IFERROR(INDEX(EstadoCuenta!$A$5:$A$30,IFERROR(SMALL(IF(EstadoCuenta!$O$5:$O$30="Por cobrar",ROW(EstadoCuenta!$O$5:$O$30)),12),"")-4),"") | C17: =IFERROR(INDEX(EstadoCuenta!$B$5:$B$30,IFERROR(SMALL(IF(EstadoCuenta!$O$5:$O$30="Por cobrar",ROW(EstadoCuenta!$O$5:$O$30)),12),"")-4),"") | D17: =IFERROR(INDEX(EstadoCuenta!$C$5:$C$30,IFERROR(SMALL(IF(EstadoCuenta!$O$5:$O$30="Por cobrar",ROW(EstadoCuenta!$O$5:$O$30)),12),"")-4),"") | E17: =IFERROR(INDEX(EstadoCuenta!$E$5:$E$30,IFERROR(SMALL(IF(EstadoCuenta!$O$5:$O$30="Por cobrar",ROW(EstadoCuenta!$O$5:$O$30)),12),"")-4),"") | F17: =IFERROR(INDEX(EstadoCuenta!$M$5:$M$30,IFERROR(SMALL(IF(EstadoCuenta!$O$5:$O$30="Por cobrar",ROW(EstadoCuenta!$O$5:$O$30)),12),"")-4),"") | G17: =IFERROR(INDEX(EstadoCuenta!$N$5:$N$30,IFERROR(SMALL(IF(EstadoCuenta!$O$5:$O$30="Por cobrar",ROW(EstadoCuenta!$O$5:$O$30)),12),"")-4),"") | H17: =IFERROR(INDEX(EstadoCuenta!$L$5:$L$30,IFERROR(SMALL(IF(EstadoCuenta!$O$5:$O$30="Por cobrar",ROW(EstadoCuenta!$O$5:$O$30)),12),"")-4),"") | I17: =IFERROR(VLOOKUP(B17,Suscripciones!$A$5:$L$30,12,FALSE),"")
A19: ▼ EN MORA
A20: Estado | B20: ID Sub | C20: Cliente | D20: Plan | E20: Precio | F20: Próx. cobro | G20: Días mora | H20: Saldo | I20: Método pago
A21: =IFERROR(INDEX(EstadoCuenta!$O$5:$O$30,IFERROR(SMALL(IF(EstadoCuenta!$O$5:$O$30="En mora",ROW(EstadoCuenta!$O$5:$O$30)),1),"")-4),"") | B21: =IFERROR(INDEX(EstadoCuenta!$A$5:$A$30,IFERROR(SMALL(IF(EstadoCuenta!$O$5:$O$30="En mora",ROW(EstadoCuenta!$O$5:$O$30)),1),"")-4),"") | C21: =IFERROR(INDEX(EstadoCuenta!$B$5:$B$30,IFERROR(SMALL(IF(EstadoCuenta!$O$5:$O$30="En mora",ROW(EstadoCuenta!$O$5:$O$30)),1),"")-4),"") | D21: =IFERROR(INDEX(EstadoCuenta!$C$5:$C$30,IFERROR(SMALL(IF(EstadoCuenta!$O$5:$O$30="En mora",ROW(EstadoCuenta!$O$5:$O$30)),1),"")-4),"") | E21: =IFERROR(INDEX(EstadoCuenta!$E$5:$E$30,IFERROR(SMALL(IF(EstadoCuenta!$O$5:$O$30="En mora",ROW(EstadoCuenta!$O$5:$O$30)),1),"")-4),"") | F21: =IFERROR(INDEX(EstadoCuenta!$M$5:$M$30,IFERROR(SMALL(IF(EstadoCuenta!$O$5:$O$30="En mora",ROW(EstadoCuenta!$O$5:$O$30)),1),"")-4),"") | G21: =IFERROR(INDEX(EstadoCuenta!$N$5:$N$30,IFERROR(SMALL(IF(EstadoCuenta!$O$5:$O$30="En mora",ROW(EstadoCuenta!$O$5:$O$30)),1),"")-4),"") | H21: =IFERROR(INDEX(EstadoCuenta!$L$5:$L$30,IFERROR(SMALL(IF(EstadoCuenta!$O$5:$O$30="En mora",ROW(EstadoCuenta!$O$5:$O$30)),1),"")-4),"") | I21: =IFERROR(VLOOKUP(B21,Suscripciones!$A$5:$L$30,12,FALSE),"")
A22: =IFERROR(INDEX(EstadoCuenta!$O$5:$O$30,IFERROR(SMALL(IF(EstadoCuenta!$O$5:$O$30="En mora",ROW(EstadoCuenta!$O$5:$O$30)),2),"")-4),"") | B22: =IFERROR(INDEX(EstadoCuenta!$A$5:$A$30,IFERROR(SMALL(IF(EstadoCuenta!$O$5:$O$30="En mora",ROW(EstadoCuenta!$O$5:$O$30)),2),"")-4),"") | C22: =IFERROR(INDEX(EstadoCuenta!$B$5:$B$30,IFERROR(SMALL(IF(EstadoCuenta!$O$5:$O$30="En mora",ROW(EstadoCuenta!$O$5:$O$30)),2),"")-4),"") | D22: =IFERROR(INDEX(EstadoCuenta!$C$5:$C$30,IFERROR(SMALL(IF(EstadoCuenta!$O$5:$O$30="En mora",ROW(EstadoCuenta!$O$5:$O$30)),2),"")-4),"") | E22: =IFERROR(INDEX(EstadoCuenta!$E$5:$E$30,IFERROR(SMALL(IF(EstadoCuenta!$O$5:$O$30="En mora",ROW(EstadoCuenta!$O$5:$O$30)),2),"")-4),"") | F22: =IFERROR(INDEX(EstadoCuenta!$M$5:$M$30,IFERROR(SMALL(IF(EstadoCuenta!$O$5:$O$30="En mora",ROW(EstadoCuenta!$O$5:$O$30)),2),"")-4),"") | G22: =IFERROR(INDEX(EstadoCuenta!$N$5:$N$30,IFERROR(SMALL(IF(EstadoCuenta!$O$5:$O$30="En mora",ROW(EstadoCuenta!$O$5:$O$30)),2),"")-4),"") | H22: =IFERROR(INDEX(EstadoCuenta!$L$5:$L$30,IFERROR(SMALL(IF(EstadoCuenta!$O$5:$O$30="En mora",ROW(EstadoCuenta!$O$5:$O$30)),2),"")-4),"") | I22: =IFERROR(VLOOKUP(B22,Suscripciones!$A$5:$L$30,12,FALSE),"")
A23: =IFERROR(INDEX(EstadoCuenta!$O$5:$O$30,IFERROR(SMALL(IF(EstadoCuenta!$O$5:$O$30="En mora",ROW(EstadoCuenta!$O$5:$O$30)),3),"")-4),"") | B23: =IFERROR(INDEX(EstadoCuenta!$A$5:$A$30,IFERROR(SMALL(IF(EstadoCuenta!$O$5:$O$30="En mora",ROW(EstadoCuenta!$O$5:$O$30)),3),"")-4),"") | C23: =IFERROR(INDEX(EstadoCuenta!$B$5:$B$30,IFERROR(SMALL(IF(EstadoCuenta!$O$5:$O$30="En mora",ROW(EstadoCuenta!$O$5:$O$30)),3),"")-4),"") | D23: =IFERROR(INDEX(EstadoCuenta!$C$5:$C$30,IFERROR(SMALL(IF(EstadoCuenta!$O$5:$O$30="En mora",ROW(EstadoCuenta!$O$5:$O$30)),3),"")-4),"") | E23: =IFERROR(INDEX(EstadoCuenta!$E$5:$E$30,IFERROR(SMALL(IF(EstadoCuenta!$O$5:$O$30="En mora",ROW(EstadoCuenta!$O$5:$O$30)),3),"")-4),"") | F23: =IFERROR(INDEX(EstadoCuenta!$M$5:$M$30,IFERROR(SMALL(IF(EstadoCuenta!$O$5:$O$30="En mora",ROW(EstadoCuenta!$O$5:$O$30)),3),"")-4),"") | G23: =IFERROR(INDEX(EstadoCuenta!$N$5:$N$30,IFERROR(SMALL(IF(EstadoCuenta!$O$5:$O$30="En mora",ROW(EstadoCuenta!$O$5:$O$30)),3),"")-4),"") | H23: =IFERROR(INDEX(EstadoCuenta!$L$5:$L$30,IFERROR(SMALL(IF(EstadoCuenta!$O$5:$O$30="En mora",ROW(EstadoCuenta!$O$5:$O$30)),3),"")-4),"") | I23: =IFERROR(VLOOKUP(B23,Suscripciones!$A$5:$L$30,12,FALSE),"")
A24: =IFERROR(INDEX(EstadoCuenta!$O$5:$O$30,IFERROR(SMALL(IF(EstadoCuenta!$O$5:$O$30="En mora",ROW(EstadoCuenta!$O$5:$O$30)),4),"")-4),"") | B24: =IFERROR(INDEX(EstadoCuenta!$A$5:$A$30,IFERROR(SMALL(IF(EstadoCuenta!$O$5:$O$30="En mora",ROW(EstadoCuenta!$O$5:$O$30)),4),"")-4),"") | C24: =IFERROR(INDEX(EstadoCuenta!$B$5:$B$30,IFERROR(SMALL(IF(EstadoCuenta!$O$5:$O$30="En mora",ROW(EstadoCuenta!$O$5:$O$30)),4),"")-4),"") | D24: =IFERROR(INDEX(EstadoCuenta!$C$5:$C$30,IFERROR(SMALL(IF(EstadoCuenta!$O$5:$O$30="En mora",ROW(EstadoCuenta!$O$5:$O$30)),4),"")-4),"") | E24: =IFERROR(INDEX(EstadoCuenta!$E$5:$E$30,IFERROR(SMALL(IF(EstadoCuenta!$O$5:$O$30="En mora",ROW(EstadoCuenta!$O$5:$O$30)),4),"")-4),"") | F24: =IFERROR(INDEX(EstadoCuenta!$M$5:$M$30,IFERROR(SMALL(IF(EstadoCuenta!$O$5:$O$30="En mora",ROW(EstadoCuenta!$O$5:$O$30)),4),"")-4),"") | G24: =IFERROR(INDEX(EstadoCuenta!$N$5:$N$30,IFERROR(SMALL(IF(EstadoCuenta!$O$5:$O$30="En mora",ROW(EstadoCuenta!$O$5:$O$30)),4),"")-4),"") | H24: =IFERROR(INDEX(EstadoCuenta!$L$5:$L$30,IFERROR(SMALL(IF(EstadoCuenta!$O$5:$O$30="En mora",ROW(EstadoCuenta!$O$5:$O$30)),4),"")-4),"") | I24: =IFERROR(VLOOKUP(B24,Suscripciones!$A$5:$L$30,12,FALSE),"")
A25: =IFERROR(INDEX(EstadoCuenta!$O$5:$O$30,IFERROR(SMALL(IF(EstadoCuenta!$O$5:$O$30="En mora",ROW(EstadoCuenta!$O$5:$O$30)),5),"")-4),"") | B25: =IFERROR(INDEX(EstadoCuenta!$A$5:$A$30,IFERROR(SMALL(IF(EstadoCuenta!$O$5:$O$30="En mora",ROW(EstadoCuenta!$O$5:$O$30)),5),"")-4),"") | C25: =IFERROR(INDEX(EstadoCuenta!$B$5:$B$30,IFERROR(SMALL(IF(EstadoCuenta!$O$5:$O$30="En mora",ROW(EstadoCuenta!$O$5:$O$30)),5),"")-4),"") | D25: =IFERROR(INDEX(EstadoCuenta!$C$5:$C$30,IFERROR(SMALL(IF(EstadoCuenta!$O$5:$O$30="En mora",ROW(EstadoCuenta!$O$5:$O$30)),5),"")-4),"") | E25: =IFERROR(INDEX(EstadoCuenta!$E$5:$E$30,IFERROR(SMALL(IF(EstadoCuenta!$O$5:$O$30="En mora",ROW(EstadoCuenta!$O$5:$O$30)),5),"")-4),"") | F25: =IFERROR(INDEX(EstadoCuenta!$M$5:$M$30,IFERROR(SMALL(IF(EstadoCuenta!$O$5:$O$30="En mora",ROW(EstadoCuenta!$O$5:$O$30)),5),"")-4),"") | G25: =IFERROR(INDEX(EstadoCuenta!$N$5:$N$30,IFERROR(SMALL(IF(EstadoCuenta!$O$5:$O$30="En mora",ROW(EstadoCuenta!$O$5:$O$30)),5),"")-4),"") | H25: =IFERROR(INDEX(EstadoCuenta!$L$5:$L$30,IFERROR(SMALL(IF(EstadoCuenta!$O$5:$O$30="En mora",ROW(EstadoCuenta!$O$5:$O$30)),5),"")-4),"") | I25: =IFERROR(VLOOKUP(B25,Suscripciones!$A$5:$L$30,12,FALSE),"")
A26: =IFERROR(INDEX(EstadoCuenta!$O$5:$O$30,IFERROR(SMALL(IF(EstadoCuenta!$O$5:$O$30="En mora",ROW(EstadoCuenta!$O$5:$O$30)),6),"")-4),"") | B26: =IFERROR(INDEX(EstadoCuenta!$A$5:$A$30,IFERROR(SMALL(IF(EstadoCuenta!$O$5:$O$30="En mora",ROW(EstadoCuenta!$O$5:$O$30)),6),"")-4),"") | C26: =IFERROR(INDEX(EstadoCuenta!$B$5:$B$30,IFERROR(SMALL(IF(EstadoCuenta!$O$5:$O$30="En mora",ROW(EstadoCuenta!$O$5:$O$30)),6),"")-4),"") | D26: =IFERROR(INDEX(EstadoCuenta!$C$5:$C$30,IFERROR(SMALL(IF(EstadoCuenta!$O$5:$O$30="En mora",ROW(EstadoCuenta!$O$5:$O$30)),6),"")-4),"") | E26: =IFERROR(INDEX(EstadoCuenta!$E$5:$E$30,IFERROR(SMALL(IF(EstadoCuenta!$O$5:$O$30="En mora",ROW(EstadoCuenta!$O$5:$O$30)),6),"")-4),"") | F26: =IFERROR(INDEX(EstadoCuenta!$M$5:$M$30,IFERROR(SMALL(IF(EstadoCuenta!$O$5:$O$30="En mora",ROW(EstadoCuenta!$O$5:$O$30)),6),"")-4),"") | G26: =IFERROR(INDEX(EstadoCuenta!$N$5:$N$30,IFERROR(SMALL(IF(EstadoCuenta!$O$5:$O$30="En mora",ROW(EstadoCuenta!$O$5:$O$30)),6),"")-4),"") | H26: =IFERROR(INDEX(EstadoCuenta!$L$5:$L$30,IFERROR(SMALL(IF(EstadoCuenta!$O$5:$O$30="En mora",ROW(EstadoCuenta!$O$5:$O$30)),6),"")-4),"") | I26: =IFERROR(VLOOKUP(B26,Suscripciones!$A$5:$L$30,12,FALSE),"")
A27: =IFERROR(INDEX(EstadoCuenta!$O$5:$O$30,IFERROR(SMALL(IF(EstadoCuenta!$O$5:$O$30="En mora",ROW(EstadoCuenta!$O$5:$O$30)),7),"")-4),"") | B27: =IFERROR(INDEX(EstadoCuenta!$A$5:$A$30,IFERROR(SMALL(IF(EstadoCuenta!$O$5:$O$30="En mora",ROW(EstadoCuenta!$O$5:$O$30)),7),"")-4),"") | C27: =IFERROR(INDEX(EstadoCuenta!$B$5:$B$30,IFERROR(SMALL(IF(EstadoCuenta!$O$5:$O$30="En mora",ROW(EstadoCuenta!$O$5:$O$30)),7),"")-4),"") | D27: =IFERROR(INDEX(EstadoCuenta!$C$5:$C$30,IFERROR(SMALL(IF(EstadoCuenta!$O$5:$O$30="En mora",ROW(EstadoCuenta!$O$5:$O$30)),7),"")-4),"") | E27: =IFERROR(INDEX(EstadoCuenta!$E$5:$E$30,IFERROR(SMALL(IF(EstadoCuenta!$O$5:$O$30="En mora",ROW(EstadoCuenta!$O$5:$O$30)),7),"")-4),"") | F27: =IFERROR(INDEX(EstadoCuenta!$M$5:$M$30,IFERROR(SMALL(IF(EstadoCuenta!$O$5:$O$30="En mora",ROW(EstadoCuenta!$O$5:$O$30)),7),"")-4),"") | G27: =IFERROR(INDEX(EstadoCuenta!$N$5:$N$30,IFERROR(SMALL(IF(EstadoCuenta!$O$5:$O$30="En mora",ROW(EstadoCuenta!$O$5:$O$30)),7),"")-4),"") | H27: =IFERROR(INDEX(EstadoCuenta!$L$5:$L$30,IFERROR(SMALL(IF(EstadoCuenta!$O$5:$O$30="En mora",ROW(EstadoCuenta!$O$5:$O$30)),7),"")-4),"") | I27: =IFERROR(VLOOKUP(B27,Suscripciones!$A$5:$L$30,12,FALSE),"")
A28: =IFERROR(INDEX(EstadoCuenta!$O$5:$O$30,IFERROR(SMALL(IF(EstadoCuenta!$O$5:$O$30="En mora",ROW(EstadoCuenta!$O$5:$O$30)),8),"")-4),"") | B28: =IFERROR(INDEX(EstadoCuenta!$A$5:$A$30,IFERROR(SMALL(IF(EstadoCuenta!$O$5:$O$30="En mora",ROW(EstadoCuenta!$O$5:$O$30)),8),"")-4),"") | C28: =IFERROR(INDEX(EstadoCuenta!$B$5:$B$30,IFERROR(SMALL(IF(EstadoCuenta!$O$5:$O$30="En mora",ROW(EstadoCuenta!$O$5:$O$30)),8),"")-4),"") | D28: =IFERROR(INDEX(EstadoCuenta!$C$5:$C$30,IFERROR(SMALL(IF(EstadoCuenta!$O$5:$O$30="En mora",ROW(EstadoCuenta!$O$5:$O$30)),8),"")-4),"") | E28: =IFERROR(INDEX(EstadoCuenta!$E$5:$E$30,IFERROR(SMALL(IF(EstadoCuenta!$O$5:$O$30="En mora",ROW(EstadoCuenta!$O$5:$O$30)),8),"")-4),"") | F28: =IFERROR(INDEX(EstadoCuenta!$M$5:$M$30,IFERROR(SMALL(IF(EstadoCuenta!$O$5:$O$30="En mora",ROW(EstadoCuenta!$O$5:$O$30)),8),"")-4),"") | G28: =IFERROR(INDEX(EstadoCuenta!$N$5:$N$30,IFERROR(SMALL(IF(EstadoCuenta!$O$5:$O$30="En mora",ROW(EstadoCuenta!$O$5:$O$30)),8),"")-4),"") | H28: =IFERROR(INDEX(EstadoCuenta!$L$5:$L$30,IFERROR(SMALL(IF(EstadoCuenta!$O$5:$O$30="En mora",ROW(EstadoCuenta!$O$5:$O$30)),8),"")-4),"") | I28: =IFERROR(VLOOKUP(B28,Suscripciones!$A$5:$L$30,12,FALSE),"")
A29: =IFERROR(INDEX(EstadoCuenta!$O$5:$O$30,IFERROR(SMALL(IF(EstadoCuenta!$O$5:$O$30="En mora",ROW(EstadoCuenta!$O$5:$O$30)),9),"")-4),"") | B29: =IFERROR(INDEX(EstadoCuenta!$A$5:$A$30,IFERROR(SMALL(IF(EstadoCuenta!$O$5:$O$30="En mora",ROW(EstadoCuenta!$O$5:$O$30)),9),"")-4),"") | C29: =IFERROR(INDEX(EstadoCuenta!$B$5:$B$30,IFERROR(SMALL(IF(EstadoCuenta!$O$5:$O$30="En mora",ROW(EstadoCuenta!$O$5:$O$30)),9),"")-4),"") | D29: =IFERROR(INDEX(EstadoCuenta!$C$5:$C$30,IFERROR(SMALL(IF(EstadoCuenta!$O$5:$O$30="En mora",ROW(EstadoCuenta!$O$5:$O$30)),9),"")-4),"") | E29: =IFERROR(INDEX(EstadoCuenta!$E$5:$E$30,IFERROR(SMALL(IF(EstadoCuenta!$O$5:$O$30="En mora",ROW(EstadoCuenta!$O$5:$O$30)),9),"")-4),"") | F29: =IFERROR(INDEX(EstadoCuenta!$M$5:$M$30,IFERROR(SMALL(IF(EstadoCuenta!$O$5:$O$30="En mora",ROW(EstadoCuenta!$O$5:$O$30)),9),"")-4),"") | G29: =IFERROR(INDEX(EstadoCuenta!$N$5:$N$30,IFERROR(SMALL(IF(EstadoCuenta!$O$5:$O$30="En mora",ROW(EstadoCuenta!$O$5:$O$30)),9),"")-4),"") | H29: =IFERROR(INDEX(EstadoCuenta!$L$5:$L$30,IFERROR(SMALL(IF(EstadoCuenta!$O$5:$O$30="En mora",ROW(EstadoCuenta!$O$5:$O$30)),9),"")-4),"") | I29: =IFERROR(VLOOKUP(B29,Suscripciones!$A$5:$L$30,12,FALSE),"")
A30: =IFERROR(INDEX(EstadoCuenta!$O$5:$O$30,IFERROR(SMALL(IF(EstadoCuenta!$O$5:$O$30="En mora",ROW(EstadoCuenta!$O$5:$O$30)),10),"")-4),"") | B30: =IFERROR(INDEX(EstadoCuenta!$A$5:$A$30,IFERROR(SMALL(IF(EstadoCuenta!$O$5:$O$30="En mora",ROW(EstadoCuenta!$O$5:$O$30)),10),"")-4),"") | C30: =IFERROR(INDEX(EstadoCuenta!$B$5:$B$30,IFERROR(SMALL(IF(EstadoCuenta!$O$5:$O$30="En mora",ROW(EstadoCuenta!$O$5:$O$30)),10),"")-4),"") | D30: =IFERROR(INDEX(EstadoCuenta!$C$5:$C$30,IFERROR(SMALL(IF(EstadoCuenta!$O$5:$O$30="En mora",ROW(EstadoCuenta!$O$5:$O$30)),10),"")-4),"") | E30: =IFERROR(INDEX(EstadoCuenta!$E$5:$E$30,IFERROR(SMALL(IF(EstadoCuenta!$O$5:$O$30="En mora",ROW(EstadoCuenta!$O$5:$O$30)),10),"")-4),"") | F30: =IFERROR(INDEX(EstadoCuenta!$M$5:$M$30,IFERROR(SMALL(IF(EstadoCuenta!$O$5:$O$30="En mora",ROW(EstadoCuenta!$O$5:$O$30)),10),"")-4),"") | G30: =IFERROR(INDEX(EstadoCuenta!$N$5:$N$30,IFERROR(SMALL(IF(EstadoCuenta!$O$5:$O$30="En mora",ROW(EstadoCuenta!$O$5:$O$30)),10),"")-4),"") | H30: =IFERROR(INDEX(EstadoCuenta!$L$5:$L$30,IFERROR(SMALL(IF(EstadoCuenta!$O$5:$O$30="En mora",ROW(EstadoCuenta!$O$5:$O$30)),10),"")-4),"") | I30: =IFERROR(VLOOKUP(B30,Suscripciones!$A$5:$L$30,12,FALSE),"")
A31: =IFERROR(INDEX(EstadoCuenta!$O$5:$O$30,IFERROR(SMALL(IF(EstadoCuenta!$O$5:$O$30="En mora",ROW(EstadoCuenta!$O$5:$O$30)),11),"")-4),"") | B31: =IFERROR(INDEX(EstadoCuenta!$A$5:$A$30,IFERROR(SMALL(IF(EstadoCuenta!$O$5:$O$30="En mora",ROW(EstadoCuenta!$O$5:$O$30)),11),"")-4),"") | C31: =IFERROR(INDEX(EstadoCuenta!$B$5:$B$30,IFERROR(SMALL(IF(EstadoCuenta!$O$5:$O$30="En mora",ROW(EstadoCuenta!$O$5:$O$30)),11),"")-4),"") | D31: =IFERROR(INDEX(EstadoCuenta!$C$5:$C$30,IFERROR(SMALL(IF(EstadoCuenta!$O$5:$O$30="En mora",ROW(EstadoCuenta!$O$5:$O$30)),11),"")-4),"") | E31: =IFERROR(INDEX(EstadoCuenta!$E$5:$E$30,IFERROR(SMALL(IF(EstadoCuenta!$O$5:$O$30="En mora",ROW(EstadoCuenta!$O$5:$O$30)),11),"")-4),"") | F31: =IFERROR(INDEX(EstadoCuenta!$M$5:$M$30,IFERROR(SMALL(IF(EstadoCuenta!$O$5:$O$30="En mora",ROW(EstadoCuenta!$O$5:$O$30)),11),"")-4),"") | G31: =IFERROR(INDEX(EstadoCuenta!$N$5:$N$30,IFERROR(SMALL(IF(EstadoCuenta!$O$5:$O$30="En mora",ROW(EstadoCuenta!$O$5:$O$30)),11),"")-4),"") | H31: =IFERROR(INDEX(EstadoCuenta!$L$5:$L$30,IFERROR(SMALL(IF(EstadoCuenta!$O$5:$O$30="En mora",ROW(EstadoCuenta!$O$5:$O$30)),11),"")-4),"") | I31: =IFERROR(VLOOKUP(B31,Suscripciones!$A$5:$L$30,12,FALSE),"")
A32: =IFERROR(INDEX(EstadoCuenta!$O$5:$O$30,IFERROR(SMALL(IF(EstadoCuenta!$O$5:$O$30="En mora",ROW(EstadoCuenta!$O$5:$O$30)),12),"")-4),"") | B32: =IFERROR(INDEX(EstadoCuenta!$A$5:$A$30,IFERROR(SMALL(IF(EstadoCuenta!$O$5:$O$30="En mora",ROW(EstadoCuenta!$O$5:$O$30)),12),"")-4),"") | C32: =IFERROR(INDEX(EstadoCuenta!$B$5:$B$30,IFERROR(SMALL(IF(EstadoCuenta!$O$5:$O$30="En mora",ROW(EstadoCuenta!$O$5:$O$30)),12),"")-4),"") | D32: =IFERROR(INDEX(EstadoCuenta!$C$5:$C$30,IFERROR(SMALL(IF(EstadoCuenta!$O$5:$O$30="En mora",ROW(EstadoCuenta!$O$5:$O$30)),12),"")-4),"") | E32: =IFERROR(INDEX(EstadoCuenta!$E$5:$E$30,IFERROR(SMALL(IF(EstadoCuenta!$O$5:$O$30="En mora",ROW(EstadoCuenta!$O$5:$O$30)),12),"")-4),"") | F32: =IFERROR(INDEX(EstadoCuenta!$M$5:$M$30,IFERROR(SMALL(IF(EstadoCuenta!$O$5:$O$30="En mora",ROW(EstadoCuenta!$O$5:$O$30)),12),"")-4),"") | G32: =IFERROR(INDEX(EstadoCuenta!$N$5:$N$30,IFERROR(SMALL(IF(EstadoCuenta!$O$5:$O$30="En mora",ROW(EstadoCuenta!$O$5:$O$30)),12),"")-4),"") | H32: =IFERROR(INDEX(EstadoCuenta!$L$5:$L$30,IFERROR(SMALL(IF(EstadoCuenta!$O$5:$O$30="En mora",ROW(EstadoCuenta!$O$5:$O$30)),12),"")-4),"") | I32: =IFERROR(VLOOKUP(B32,Suscripciones!$A$5:$L$30,12,FALSE),"")

Sheet EstadoCuenta
A1: 🧾 ESTADO DE CUENTA
A2: Saldo, mora y próximo cobro por suscripción · todo automático desde Suscripciones + Pagos
A4: ID Sub | B4: Cliente | C4: Plan | D4: Periodicidad | E4: Precio | F4: Inicio | G4: Día cobro | H4: Cuotas esperadas | I4: Total facturado | J4: Cuotas pagadas | K4: Total pagado | L4: Saldo pendiente | M4: Próximo cobro | N4: Días para cobro | O4: Estado pago
A5: =IF(Suscripciones!A5="","",Suscripciones!A5) | B5: =IF(Suscripciones!A5="","",Suscripciones!C5) | C5: =IF(Suscripciones!A5="","",Suscripciones!E5) | D5: =IF(Suscripciones!A5="","",Suscripciones!F5) | E5: =IF(Suscripciones!A5="","",Suscripciones!G5) | F5: =IF(Suscripciones!A5="","",Suscripciones!H5) | G5: =IF(Suscripciones!A5="","",Suscripciones!I5) | H5: =IF(Suscripciones!A5="","",IF(Suscripciones!J5<>"Activa",0,IF(Suscripciones!F5="Anual", MAX(0,DATEDIF(Suscripciones!H5,TODAY(),"Y")+1), MAX(0,DATEDIF(Suscripciones!H5,TODAY(),"M")+1)))) | I5: =IF(A5="","",H5*E5) | J5: =IF(A5="","",COUNTIFS(Pagos!C:C,A5)) | K5: =IF(A5="","",SUMIFS(Pagos!F:F,Pagos!C:C,A5)) | L5: =IF(A5="","",I5-K5) | M5: =IF(A5="","",IF(Suscripciones!J5<>"Activa","",IF(D5="Anual", DATE(YEAR(F5)+J5,MONTH(F5),DAY(F5)), EDATE(F5,J5)))) | N5: =IF(OR(A5="",M5=""),"",M5-TODAY()) | O5: =IF(A5="","",IF(Suscripciones!J5<>"Activa",Suscripciones!J5,IF(L5<=0,"Al día",IF(N5<0,"En mora",IF(N5<=7,"Por cobrar","Próximo")))))
A6: =IF(Suscripciones!A6="","",Suscripciones!A6) | B6: =IF(Suscripciones!A6="","",Suscripciones!C6) | C6: =IF(Suscripciones!A6="","",Suscripciones!E6) | D6: =IF(Suscripciones!A6="","",Suscripciones!F6) | E6: =IF(Suscripciones!A6="","",Suscripciones!G6) | F6: =IF(Suscripciones!A6="","",Suscripciones!H6) | G6: =IF(Suscripciones!A6="","",Suscripciones!I6) | H6: =IF(Suscripciones!A6="","",IF(Suscripciones!J6<>"Activa",0,IF(Suscripciones!F6="Anual", MAX(0,DATEDIF(Suscripciones!H6,TODAY(),"Y")+1), MAX(0,DATEDIF(Suscripciones!H6,TODAY(),"M")+1)))) | I6: =IF(A6="","",H6*E6) | J6: =IF(A6="","",COUNTIFS(Pagos!C:C,A6)) | K6: =IF(A6="","",SUMIFS(Pagos!F:F,Pagos!C:C,A6)) | L6: =IF(A6="","",I6-K6) | M6: =IF(A6="","",IF(Suscripciones!J6<>"Activa","",IF(D6="Anual", DATE(YEAR(F6)+J6,MONTH(F6),DAY(F6)), EDATE(F6,J6)))) | N6: =IF(OR(A6="",M6=""),"",M6-TODAY()) | O6: =IF(A6="","",IF(Suscripciones!J6<>"Activa",Suscripciones!J6,IF(L6<=0,"Al día",IF(N6<0,"En mora",IF(N6<=7,"Por cobrar","Próximo")))))
A7: =IF(Suscripciones!A7="","",Suscripciones!A7) | B7: =IF(Suscripciones!A7="","",Suscripciones!C7) | C7: =IF(Suscripciones!A7="","",Suscripciones!E7) | D7: =IF(Suscripciones!A7="","",Suscripciones!F7) | E7: =IF(Suscripciones!A7="","",Suscripciones!G7) | F7: =IF(Suscripciones!A7="","",Suscripciones!H7) | G7: =IF(Suscripciones!A7="","",Suscripciones!I7) | H7: =IF(Suscripciones!A7="","",IF(Suscripciones!J7<>"Activa",0,IF(Suscripciones!F7="Anual", MAX(0,DATEDIF(Suscripciones!H7,TODAY(),"Y")+1), MAX(0,DATEDIF(Suscripciones!H7,TODAY(),"M")+1)))) | I7: =IF(A7="","",H7*E7) | J7: =IF(A7="","",COUNTIFS(Pagos!C:C,A7)) | K7: =IF(A7="","",SUMIFS(Pagos!F:F,Pagos!C:C,A7)) | L7: =IF(A7="","",I7-K7) | M7: =IF(A7="","",IF(Suscripciones!J7<>"Activa","",IF(D7="Anual", DATE(YEAR(F7)+J7,MONTH(F7),DAY(F7)), EDATE(F7,J7)))) | N7: =IF(OR(A7="",M7=""),"",M7-TODAY()) | O7: =IF(A7="","",IF(Suscripciones!J7<>"Activa",Suscripciones!J7,IF(L7<=0,"Al día",IF(N7<0,"En mora",IF(N7<=7,"Por cobrar","Próximo")))))
A8: =IF(Suscripciones!A8="","",Suscripciones!A8) | B8: =IF(Suscripciones!A8="","",Suscripciones!C8) | C8: =IF(Suscripciones!A8="","",Suscripciones!E8) | D8: =IF(Suscripciones!A8="","",Suscripciones!F8) | E8: =IF(Suscripciones!A8="","",Suscripciones!G8) | F8: =IF(Suscripciones!A8="","",Suscripciones!H8) | G8: =IF(Suscripciones!A8="","",Suscripciones!I8) | H8: =IF(Suscripciones!A8="","",IF(Suscripciones!J8<>"Activa",0,IF(Suscripciones!F8="Anual", MAX(0,DATEDIF(Suscripciones!H8,TODAY(),"Y")+1), MAX(0,DATEDIF(Suscripciones!H8,TODAY(),"M")+1)))) | I8: =IF(A8="","",H8*E8) | J8: =IF(A8="","",COUNTIFS(Pagos!C:C,A8)) | K8: =IF(A8="","",SUMIFS(Pagos!F:F,Pagos!C:C,A8)) | L8: =IF(A8="","",I8-K8) | M8: =IF(A8="","",IF(Suscripciones!J8<>"Activa","",IF(D8="Anual", DATE(YEAR(F8)+J8,MONTH(F8),DAY(F8)), EDATE(F8,J8)))) | N8: =IF(OR(A8="",M8=""),"",M8-TODAY()) | O8: =IF(A8="","",IF(Suscripciones!J8<>"Activa",Suscripciones!J8,IF(L8<=0,"Al día",IF(N8<0,"En mora",IF(N8<=7,"Por cobrar","Próximo")))))
A9: =IF(Suscripciones!A9="","",Suscripciones!A9) | B9: =IF(Suscripciones!A9="","",Suscripciones!C9) | C9: =IF(Suscripciones!A9="","",Suscripciones!E9) | D9: =IF(Suscripciones!A9="","",Suscripciones!F9) | E9: =IF(Suscripciones!A9="","",Suscripciones!G9) | F9: =IF(Suscripciones!A9="","",Suscripciones!H9) | G9: =IF(Suscripciones!A9="","",Suscripciones!I9) | H9: =IF(Suscripciones!A9="","",IF(Suscripciones!J9<>"Activa",0,IF(Suscripciones!F9="Anual", MAX(0,DATEDIF(Suscripciones!H9,TODAY(),"Y")+1), MAX(0,DATEDIF(Suscripciones!H9,TODAY(),"M")+1)))) | I9: =IF(A9="","",H9*E9) | J9: =IF(A9="","",COUNTIFS(Pagos!C:C,A9)) | K9: =IF(A9="","",SUMIFS(Pagos!F:F,Pagos!C:C,A9)) | L9: =IF(A9="","",I9-K9) | M9: =IF(A9="","",IF(Suscripciones!J9<>"Activa","",IF(D9="Anual", DATE(YEAR(F9)+J9,MONTH(F9),DAY(F9)), EDATE(F9,J9)))) | N9: =IF(OR(A9="",M9=""),"",M9-TODAY()) | O9: =IF(A9="","",IF(Suscripciones!J9<>"Activa",Suscripciones!J9,IF(L9<=0,"Al día",IF(N9<0,"En mora",IF(N9<=7,"Por cobrar","Próximo")))))
A10: =IF(Suscripciones!A10="","",Suscripciones!A10) | B10: =IF(Suscripciones!A10="","",Suscripciones!C10) | C10: =IF(Suscripciones!A10="","",Suscripciones!E10) | D10: =IF(Suscripciones!A10="","",Suscripciones!F10) | E10: =IF(Suscripciones!A10="","",Suscripciones!G10) | F10: =IF(Suscripciones!A10="","",Suscripciones!H10) | G10: =IF(Suscripciones!A10="","",Suscripciones!I10) | H10: =IF(Suscripciones!A10="","",IF(Suscripciones!J10<>"Activa",0,IF(Suscripciones!F10="Anual", MAX(0,DATEDIF(Suscripciones!H10,TODAY(),"Y")+1), MAX(0,DATEDIF(Suscripciones!H10,TODAY(),"M")+1)))) | I10: =IF(A10="","",H10*E10) | J10: =IF(A10="","",COUNTIFS(Pagos!C:C,A10)) | K10: =IF(A10="","",SUMIFS(Pagos!F:F,Pagos!C:C,A10)) | L10: =IF(A10="","",I10-K10) | M10: =IF(A10="","",IF(Suscripciones!J10<>"Activa","",IF(D10="Anual", DATE(YEAR(F10)+J10,MONTH(F10),DAY(F10)), EDATE(F10,J10)))) | N10: =IF(OR(A10="",M10=""),"",M10-TODAY()) | O10: =IF(A10="","",IF(Suscripciones!J10<>"Activa",Suscripciones!J10,IF(L10<=0,"Al día",IF(N10<0,"En mora",IF(N10<=7,"Por cobrar","Próximo")))))
A11: =IF(Suscripciones!A11="","",Suscripciones!A11) | B11: =IF(Suscripciones!A11="","",Suscripciones!C11) | C11: =IF(Suscripciones!A11="","",Suscripciones!E11) | D11: =IF(Suscripciones!A11="","",Suscripciones!F11) | E11: =IF(Suscripciones!A11="","",Suscripciones!G11) | F11: =IF(Suscripciones!A11="","",Suscripciones!H11) | G11: =IF(Suscripciones!A11="","",Suscripciones!I11) | H11: =IF(Suscripciones!A11="","",IF(Suscripciones!J11<>"Activa",0,IF(Suscripciones!F11="Anual", MAX(0,DATEDIF(Suscripciones!H11,TODAY(),"Y")+1), MAX(0,DATEDIF(Suscripciones!H11,TODAY(),"M")+1)))) | I11: =IF(A11="","",H11*E11) | J11: =IF(A11="","",COUNTIFS(Pagos!C:C,A11)) | K11: =IF(A11="","",SUMIFS(Pagos!F:F,Pagos!C:C,A11)) | L11: =IF(A11="","",I11-K11) | M11: =IF(A11="","",IF(Suscripciones!J11<>"Activa","",IF(D11="Anual", DATE(YEAR(F11)+J11,MONTH(F11),DAY(F11)), EDATE(F11,J11)))) | N11: =IF(OR(A11="",M11=""),"",M11-TODAY()) | O11: =IF(A11="","",IF(Suscripciones!J11<>"Activa",Suscripciones!J11,IF(L11<=0,"Al día",IF(N11<0,"En mora",IF(N11<=7,"Por cobrar","Próximo")))))
A12: =IF(Suscripciones!A12="","",Suscripciones!A12) | B12: =IF(Suscripciones!A12="","",Suscripciones!C12) | C12: =IF(Suscripciones!A12="","",Suscripciones!E12) | D12: =IF(Suscripciones!A12="","",Suscripciones!F12) | E12: =IF(Suscripciones!A12="","",Suscripciones!G12) | F12: =IF(Suscripciones!A12="","",Suscripciones!H12) | G12: =IF(Suscripciones!A12="","",Suscripciones!I12) | H12: =IF(Suscripciones!A12="","",IF(Suscripciones!J12<>"Activa",0,IF(Suscripciones!F12="Anual", MAX(0,DATEDIF(Suscripciones!H12,TODAY(),"Y")+1), MAX(0,DATEDIF(Suscripciones!H12,TODAY(),"M")+1)))) | I12: =IF(A12="","",H12*E12) | J12: =IF(A12="","",COUNTIFS(Pagos!C:C,A12)) | K12: =IF(A12="","",SUMIFS(Pagos!F:F,Pagos!C:C,A12)) | L12: =IF(A12="","",I12-K12) | M12: =IF(A12="","",IF(Suscripciones!J12<>"Activa","",IF(D12="Anual", DATE(YEAR(F12)+J12,MONTH(F12),DAY(F12)), EDATE(F12,J12)))) | N12: =IF(OR(A12="",M12=""),"",M12-TODAY()) | O12: =IF(A12="","",IF(Suscripciones!J12<>"Activa",Suscripciones!J12,IF(L12<=0,"Al día",IF(N12<0,"En mora",IF(N12<=7,"Por cobrar","Próximo")))))
A13: =IF(Suscripciones!A13="","",Suscripciones!A13) | B13: =IF(Suscripciones!A13="","",Suscripciones!C13) | C13: =IF(Suscripciones!A13="","",Suscripciones!E13) | D13: =IF(Suscripciones!A13="","",Suscripciones!F13) | E13: =IF(Suscripciones!A13="","",Suscripciones!G13) | F13: =IF(Suscripciones!A13="","",Suscripciones!H13) | G13: =IF(Suscripciones!A13="","",Suscripciones!I13) | H13: =IF(Suscripciones!A13="","",IF(Suscripciones!J13<>"Activa",0,IF(Suscripciones!F13="Anual", MAX(0,DATEDIF(Suscripciones!H13,TODAY(),"Y")+1), MAX(0,DATEDIF(Suscripciones!H13,TODAY(),"M")+1)))) | I13: =IF(A13="","",H13*E13) | J13: =IF(A13="","",COUNTIFS(Pagos!C:C,A13)) | K13: =IF(A13="","",SUMIFS(Pagos!F:F,Pagos!C:C,A13)) | L13: =IF(A13="","",I13-K13) | M13: =IF(A13="","",IF(Suscripciones!J13<>"Activa","",IF(D13="Anual", DATE(YEAR(F13)+J13,MONTH(F13),DAY(F13)), EDATE(F13,J13)))) | N13: =IF(OR(A13="",M13=""),"",M13-TODAY()) | O13: =IF(A13="","",IF(Suscripciones!J13<>"Activa",Suscripciones!J13,IF(L13<=0,"Al día",IF(N13<0,"En mora",IF(N13<=7,"Por cobrar","Próximo")))))
A14: =IF(Suscripciones!A14="","",Suscripciones!A14) | B14: =IF(Suscripciones!A14="","",Suscripciones!C14) | C14: =IF(Suscripciones!A14="","",Suscripciones!E14) | D14: =IF(Suscripciones!A14="","",Suscripciones!F14) | E14: =IF(Suscripciones!A14="","",Suscripciones!G14) | F14: =IF(Suscripciones!A14="","",Suscripciones!H14) | G14: =IF(Suscripciones!A14="","",Suscripciones!I14) | H14: =IF(Suscripciones!A14="","",IF(Suscripciones!J14<>"Activa",0,IF(Suscripciones!F14="Anual", MAX(0,DATEDIF(Suscripciones!H14,TODAY(),"Y")+1), MAX(0,DATEDIF(Suscripciones!H14,TODAY(),"M")+1)))) | I14: =IF(A14="","",H14*E14) | J14: =IF(A14="","",COUNTIFS(Pagos!C:C,A14)) | K14: =IF(A14="","",SUMIFS(Pagos!F:F,Pagos!C:C,A14)) | L14: =IF(A14="","",I14-K14) | M14: =IF(A14="","",IF(Suscripciones!J14<>"Activa","",IF(D14="Anual", DATE(YEAR(F14)+J14,MONTH(F14),DAY(F14)), EDATE(F14,J14)))) | N14: =IF(OR(A14="",M14=""),"",M14-TODAY()) | O14: =IF(A14="","",IF(Suscripciones!J14<>"Activa",Suscripciones!J14,IF(L14<=0,"Al día",IF(N14<0,"En mora",IF(N14<=7,"Por cobrar","Próximo")))))
A15: =IF(Suscripciones!A15="","",Suscripciones!A15) | B15: =IF(Suscripciones!A15="","",Suscripciones!C15) | C15: =IF(Suscripciones!A15="","",Suscripciones!E15) | D15: =IF(Suscripciones!A15="","",Suscripciones!F15) | E15: =IF(Suscripciones!A15="","",Suscripciones!G15) | F15: =IF(Suscripciones!A15="","",Suscripciones!H15) | G15: =IF(Suscripciones!A15="","",Suscripciones!I15) | H15: =IF(Suscripciones!A15="","",IF(Suscripciones!J15<>"Activa",0,IF(Suscripciones!F15="Anual", MAX(0,DATEDIF(Suscripciones!H15,TODAY(),"Y")+1), MAX(0,DATEDIF(Suscripciones!H15,TODAY(),"M")+1)))) | I15: =IF(A15="","",H15*E15) | J15: =IF(A15="","",COUNTIFS(Pagos!C:C,A15)) | K15: =IF(A15="","",SUMIFS(Pagos!F:F,Pagos!C:C,A15)) | L15: =IF(A15="","",I15-K15) | M15: =IF(A15="","",IF(Suscripciones!J15<>"Activa","",IF(D15="Anual", DATE(YEAR(F15)+J15,MONTH(F15),DAY(F15)), EDATE(F15,J15)))) | N15: =IF(OR(A15="",M15=""),"",M15-TODAY()) | O15: =IF(A15="","",IF(Suscripciones!J15<>"Activa",Suscripciones!J15,IF(L15<=0,"Al día",IF(N15<0,"En mora",IF(N15<=7,"Por cobrar","Próximo")))))
A16: =IF(Suscripciones!A16="","",Suscripciones!A16) | B16: =IF(Suscripciones!A16="","",Suscripciones!C16) | C16: =IF(Suscripciones!A16="","",Suscripciones!E16) | D16: =IF(Suscripciones!A16="","",Suscripciones!F16) | E16: =IF(Suscripciones!A16="","",Suscripciones!G16) | F16: =IF(Suscripciones!A16="","",Suscripciones!H16) | G16: =IF(Suscripciones!A16="","",Suscripciones!I16) | H16: =IF(Suscripciones!A16="","",IF(Suscripciones!J16<>"Activa",0,IF(Suscripciones!F16="Anual", MAX(0,DATEDIF(Suscripciones!H16,TODAY(),"Y")+1), MAX(0,DATEDIF(Suscripciones!H16,TODAY(),"M")+1)))) | I16: =IF(A16="","",H16*E16) | J16: =IF(A16="","",COUNTIFS(Pagos!C:C,A16)) | K16: =IF(A16="","",SUMIFS(Pagos!F:F,Pagos!C:C,A16)) | L16: =IF(A16="","",I16-K16) | M16: =IF(A16="","",IF(Suscripciones!J16<>"Activa","",IF(D16="Anual", DATE(YEAR(F16)+J16,MONTH(F16),DAY(F16)), EDATE(F16,J16)))) | N16: =IF(OR(A16="",M16=""),"",M16-TODAY()) | O16: =IF(A16="","",IF(Suscripciones!J16<>"Activa",Suscripciones!J16,IF(L16<=0,"Al día",IF(N16<0,"En mora",IF(N16<=7,"Por cobrar","Próximo")))))
... A30: =IF(Suscripciones!A30="","",Suscripciones!A30) | B30: =IF(Suscripciones!A30="","",Suscripciones!C30) | C30: =IF(Suscripciones!A30="","",Suscripciones!E30) | D30: =IF(Suscripciones!A30="","",Suscripciones!F30) | E30: =IF(Suscripciones!A30="","",Suscripciones!G30) | F30: =IF(Suscripciones!A30="","",Suscripciones!H30) | G30: =IF(Suscripciones!A30="","",Suscripciones!I30) | H30: =IF(Suscripciones!A30="","",IF(Suscripciones!J30<>"Activa",0,IF(Suscripciones!F30="Anual", MAX(0,DATEDIF(Suscripciones!H30,TODAY(),"Y")+1), MAX(0,DATEDIF(Suscripciones!H30,TODAY(),"M")+1)))) | I30: =IF(A30="","",H30*E30) | J30: =IF(A30="","",COUNTIFS(Pagos!C:C,A30)) | K30: =IF(A30="","",SUMIFS(Pagos!F:F,Pagos!C:C,A30)) | L30: =IF(A30="","",I30-K30) | M30: =IF(A30="","",IF(Suscripciones!J30<>"Activa","",IF(D30="Anual", DATE(YEAR(F30)+J30,MONTH(F30),DAY(F30)), EDATE(F30,J30)))) | N30: =IF(OR(A30="",M30=""),"",M30-TODAY()) | O30: =IF(A30="","",IF(Suscripciones!J30<>"Activa",Suscripciones!J30,IF(L30<=0,"Al día",IF(N30<0,"En mora",IF(N30<=7,"Por cobrar","Próximo")))))

Sheet Suscripciones
A1: 📌 SUSCRIPCIONES
A2: Una fila por suscripción · campos auto-calculados desde Planes y Clientes
A4: ID Sub | B4: ID Cliente | C4: Cliente (auto) | D4: ID Plan | E4: Plan (auto) | F4: Periodicidad (auto) | G4: Precio (auto) | H4: Fecha inicio | I4: Día de cobro | J4: Estado | K4: Auto-renov | L4: Método pago | M4: Notas
A5: SUB-0001 | B5: CLI-001 | C5: =IFERROR(VLOOKUP(B5,TBL_CLIENTES,2,FALSE),"") | D5: PLAN-PRO | E5: =IFERROR(VLOOKUP(D5,TBL_PLANES,2,FALSE),"") | F5: =IFERROR(VLOOKUP(D5,TBL_PLANES,3,FALSE),"") | G5: =IFERROR(VLOOKUP(D5,TBL_PLANES,4,FALSE),"") | H5: 46082 | I5: 1 | J5: Activa | K5: Sí | L5: Transferencia
A6: SUB-0002 | B6: CLI-002 | C6: =IFERROR(VLOOKUP(B6,TBL_CLIENTES,2,FALSE),"") | D6: PLAN-BASIC | E6: =IFERROR(VLOOKUP(D6,TBL_PLANES,2,FALSE),"") | F6: =IFERROR(VLOOKUP(D6,TBL_PLANES,3,FALSE),"") | G6: =IFERROR(VLOOKUP(D6,TBL_PLANES,4,FALSE),"") | H6: 46117 | I6: 5 | J6: Activa | K6: Sí | L6: Transferencia
A7: SUB-0003 | B7: CLI-003 | C7: =IFERROR(VLOOKUP(B7,TBL_CLIENTES,2,FALSE),"") | D7: PLAN-ELITE | E7: =IFERROR(VLOOKUP(D7,TBL_PLANES,2,FALSE),"") | F7: =IFERROR(VLOOKUP(D7,TBL_PLANES,3,FALSE),"") | G7: =IFERROR(VLOOKUP(D7,TBL_PLANES,4,FALSE),"") | H7: 46037 | I7: 15 | J7: Activa | K7: Sí | L7: Tarjeta | M7: Premium
A8: SUB-0004 | B8: CLI-004 | C8: =IFERROR(VLOOKUP(B8,TBL_CLIENTES,2,FALSE),"") | D8: PLAN-PRO | E8: =IFERROR(VLOOKUP(D8,TBL_PLANES,2,FALSE),"") | F8: =IFERROR(VLOOKUP(D8,TBL_PLANES,3,FALSE),"") | G8: =IFERROR(VLOOKUP(D8,TBL_PLANES,4,FALSE),"") | H8: 46132 | I8: 20 | J8: Activa | K8: No | L8: Efectivo | M8: Cobro manual
A9: SUB-0005 | B9: CLI-005 | C9: =IFERROR(VLOOKUP(B9,TBL_CLIENTES,2,FALSE),"") | D9: PLAN-ANUAL | E9: =IFERROR(VLOOKUP(D9,TBL_PLANES,2,FALSE),"") | F9: =IFERROR(VLOOKUP(D9,TBL_PLANES,3,FALSE),"") | G9: =IFERROR(VLOOKUP(D9,TBL_PLANES,4,FALSE),"") | H9: 46054 | I9: 1 | J9: Activa | K9: Sí | L9: Transferencia
A10: SUB-0006 | B10: CLI-006 | C10: =IFERROR(VLOOKUP(B10,TBL_CLIENTES,2,FALSE),"") | D10: PLAN-BASIC | E10: =IFERROR(VLOOKUP(D10,TBL_PLANES,2,FALSE),"") | F10: =IFERROR(VLOOKUP(D10,TBL_PLANES,3,FALSE),"") | G10: =IFERROR(VLOOKUP(D10,TBL_PLANES,4,FALSE),"") | H10: 46137 | I10: 25 | J10: Pausada | K10: No | L10: Transferencia | M10: Trial
C11: =IFERROR(VLOOKUP(B11,TBL_CLIENTES,2,FALSE),"") | E11: =IFERROR(VLOOKUP(D11,TBL_PLANES,2,FALSE),"") | F11: =IFERROR(VLOOKUP(D11,TBL_PLANES,3,FALSE),"") | G11: =IFERROR(VLOOKUP(D11,TBL_PLANES,4,FALSE),"")
C12: =IFERROR(VLOOKUP(B12,TBL_CLIENTES,2,FALSE),"") | E12: =IFERROR(VLOOKUP(D12,TBL_PLANES,2,FALSE),"") | F12: =IFERROR(VLOOKUP(D12,TBL_PLANES,3,FALSE),"") | G12: =IFERROR(VLOOKUP(D12,TBL_PLANES,4,FALSE),"")
C13: =IFERROR(VLOOKUP(B13,TBL_CLIENTES,2,FALSE),"") | E13: =IFERROR(VLOOKUP(D13,TBL_PLANES,2,FALSE),"") | F13: =IFERROR(VLOOKUP(D13,TBL_PLANES,3,FALSE),"") | G13: =IFERROR(VLOOKUP(D13,TBL_PLANES,4,FALSE),"")
C14: =IFERROR(VLOOKUP(B14,TBL_CLIENTES,2,FALSE),"") | E14: =IFERROR(VLOOKUP(D14,TBL_PLANES,2,FALSE),"") | F14: =IFERROR(VLOOKUP(D14,TBL_PLANES,3,FALSE),"") | G14: =IFERROR(VLOOKUP(D14,TBL_PLANES,4,FALSE),"")
C15: =IFERROR(VLOOKUP(B15,TBL_CLIENTES,2,FALSE),"") | E15: =IFERROR(VLOOKUP(D15,TBL_PLANES,2,FALSE),"") | F15: =IFERROR(VLOOKUP(D15,TBL_PLANES,3,FALSE),"") | G15: =IFERROR(VLOOKUP(D15,TBL_PLANES,4,FALSE),"")
C16: =IFERROR(VLOOKUP(B16,TBL_CLIENTES,2,FALSE),"") | E16: =IFERROR(VLOOKUP(D16,TBL_PLANES,2,FALSE),"") | F16: =IFERROR(VLOOKUP(D16,TBL_PLANES,3,FALSE),"") | G16: =IFERROR(VLOOKUP(D16,TBL_PLANES,4,FALSE),"")
C17: =IFERROR(VLOOKUP(B17,TBL_CLIENTES,2,FALSE),"") | E17: =IFERROR(VLOOKUP(D17,TBL_PLANES,2,FALSE),"") | F17: =IFERROR(VLOOKUP(D17,TBL_PLANES,3,FALSE),"") | G17: =IFERROR(VLOOKUP(D17,TBL_PLANES,4,FALSE),"")
C18: =IFERROR(VLOOKUP(B18,TBL_CLIENTES,2,FALSE),"") | E18: =IFERROR(VLOOKUP(D18,TBL_PLANES,2,FALSE),"") | F18: =IFERROR(VLOOKUP(D18,TBL_PLANES,3,FALSE),"") | G18: =IFERROR(VLOOKUP(D18,TBL_PLANES,4,FALSE),"")
C19: =IFERROR(VLOOKUP(B19,TBL_CLIENTES,2,FALSE),"") | E19: =IFERROR(VLOOKUP(D19,TBL_PLANES,2,FALSE),"") | F19: =IFERROR(VLOOKUP(D19,TBL_PLANES,3,FALSE),"") | G19: =IFERROR(VLOOKUP(D19,TBL_PLANES,4,FALSE),"")
C20: =IFERROR(VLOOKUP(B20,TBL_CLIENTES,2,FALSE),"") | E20: =IFERROR(VLOOKUP(D20,TBL_PLANES,2,FALSE),"") | F20: =IFERROR(VLOOKUP(D20,TBL_PLANES,3,FALSE),"") | G20: =IFERROR(VLOOKUP(D20,TBL_PLANES,4,FALSE),"")
C21: =IFERROR(VLOOKUP(B21,TBL_CLIENTES,2,FALSE),"") | E21: =IFERROR(VLOOKUP(D21,TBL_PLANES,2,FALSE),"") | F21: =IFERROR(VLOOKUP(D21,TBL_PLANES,3,FALSE),"") | G21: =IFERROR(VLOOKUP(D21,TBL_PLANES,4,FALSE),"")
C22: =IFERROR(VLOOKUP(B22,TBL_CLIENTES,2,FALSE),"") | E22: =IFERROR(VLOOKUP(D22,TBL_PLANES,2,FALSE),"") | F22: =IFERROR(VLOOKUP(D22,TBL_PLANES,3,FALSE),"") | G22: =IFERROR(VLOOKUP(D22,TBL_PLANES,4,FALSE),"")
... C29: =IFERROR(VLOOKUP(B29,TBL_CLIENTES,2,FALSE),"") | E29: =IFERROR(VLOOKUP(D29,TBL_PLANES,2,FALSE),"") | F29: =IFERROR(VLOOKUP(D29,TBL_PLANES,3,FALSE),"") | G29: =IFERROR(VLOOKUP(D29,TBL_PLANES,4,FALSE),"")

Sheet Pagos
A1: 💳 PAGOS
A2: Histórico de cobros · cada fila es un pago realizado
A4: ID Pago | B4: Fecha pago | C4: ID Sub | D4: Cliente (auto) | E4: Plan (auto) | F4: Monto | G4: Método | H4: Período cubierto | I4: Notas
A5: PAG-0001 | B5: 46082 | C5: SUB-0001 | D5: =IFERROR(VLOOKUP(C5,TBL_SUB,3,FALSE),"") | E5: =IFERROR(VLOOKUP(C5,TBL_SUB,5,FALSE),"") | F5: 80 | G5: Transferencia | H5: 2026-03
A6: PAG-0002 | B6: 46113 | C6: SUB-0001 | D6: =IFERROR(VLOOKUP(C6,TBL_SUB,3,FALSE),"") | E6: =IFERROR(VLOOKUP(C6,TBL_SUB,5,FALSE),"") | F6: 80 | G6: Transferencia | H6: 2026-04
A7: PAG-0003 | B7: 46117 | C7: SUB-0002 | D7: =IFERROR(VLOOKUP(C7,TBL_SUB,3,FALSE),"") | E7: =IFERROR(VLOOKUP(C7,TBL_SUB,5,FALSE),"") | F7: 40 | G7: Transferencia | H7: 2026-04
A8: PAG-0004 | B8: 46037 | C8: SUB-0003 | D8: =IFERROR(VLOOKUP(C8,TBL_SUB,3,FALSE),"") | E8: =IFERROR(VLOOKUP(C8,TBL_SUB,5,FALSE),"") | F8: 150 | G8: Tarjeta | H8: 2026-01
A9: PAG-0005 | B9: 46068 | C9: SUB-0003 | D9: =IFERROR(VLOOKUP(C9,TBL_SUB,3,FALSE),"") | E9: =IFERROR(VLOOKUP(C9,TBL_SUB,5,FALSE),"") | F9: 150 | G9: Tarjeta | H9: 2026-02
A10: PAG-0006 | B10: 46096 | C10: SUB-0003 | D10: =IFERROR(VLOOKUP(C10,TBL_SUB,3,FALSE),"") | E10: =IFERROR(VLOOKUP(C10,TBL_SUB,5,FALSE),"") | F10: 150 | G10: Tarjeta | H10: 2026-03
A11: PAG-0007 | B11: 46127 | C11: SUB-0003 | D11: =IFERROR(VLOOKUP(C11,TBL_SUB,3,FALSE),"") | E11: =IFERROR(VLOOKUP(C11,TBL_SUB,5,FALSE),"") | F11: 150 | G11: Tarjeta | H11: 2026-04
A12: PAG-0008 | B12: 46132 | C12: SUB-0004 | D12: =IFERROR(VLOOKUP(C12,TBL_SUB,3,FALSE),"") | E12: =IFERROR(VLOOKUP(C12,TBL_SUB,5,FALSE),"") | F12: 80 | G12: Efectivo | H12: 2026-04
A13: PAG-0009 | B13: 46054 | C13: SUB-0005 | D13: =IFERROR(VLOOKUP(C13,TBL_SUB,3,FALSE),"") | E13: =IFERROR(VLOOKUP(C13,TBL_SUB,5,FALSE),"") | F13: 800 | G13: Transferencia | H13: 2026 anual | I13: Plan anual completo
D14: =IFERROR(VLOOKUP(C14,TBL_SUB,3,FALSE),"") | E14: =IFERROR(VLOOKUP(C14,TBL_SUB,5,FALSE),"")
D15: =IFERROR(VLOOKUP(C15,TBL_SUB,3,FALSE),"") | E15: =IFERROR(VLOOKUP(C15,TBL_SUB,5,FALSE),"")
D16: =IFERROR(VLOOKUP(C16,TBL_SUB,3,FALSE),"") | E16: =IFERROR(VLOOKUP(C16,TBL_SUB,5,FALSE),"")
D17: =IFERROR(VLOOKUP(C17,TBL_SUB,3,FALSE),"") | E17: =IFERROR(VLOOKUP(C17,TBL_SUB,5,FALSE),"")
D18: =IFERROR(VLOOKUP(C18,TBL_SUB,3,FALSE),"") | E18: =IFERROR(VLOOKUP(C18,TBL_SUB,5,FALSE),"")
D19: =IFERROR(VLOOKUP(C19,TBL_SUB,3,FALSE),"") | E19: =IFERROR(VLOOKUP(C19,TBL_SUB,5,FALSE),"")
D20: =IFERROR(VLOOKUP(C20,TBL_SUB,3,FALSE),"") | E20: =IFERROR(VLOOKUP(C20,TBL_SUB,5,FALSE),"")
D21: =IFERROR(VLOOKUP(C21,TBL_SUB,3,FALSE),"") | E21: =IFERROR(VLOOKUP(C21,TBL_SUB,5,FALSE),"")
D22: =IFERROR(VLOOKUP(C22,TBL_SUB,3,FALSE),"") | E22: =IFERROR(VLOOKUP(C22,TBL_SUB,5,FALSE),"")
D23: =IFERROR(VLOOKUP(C23,TBL_SUB,3,FALSE),"") | E23: =IFERROR(VLOOKUP(C23,TBL_SUB,5,FALSE),"")
D24: =IFERROR(VLOOKUP(C24,TBL_SUB,3,FALSE),"") | E24: =IFERROR(VLOOKUP(C24,TBL_SUB,5,FALSE),"")
D25: =IFERROR(VLOOKUP(C25,TBL_SUB,3,FALSE),"") | E25: =IFERROR(VLOOKUP(C25,TBL_SUB,5,FALSE),"")
... D49: =IFERROR(VLOOKUP(C49,TBL_SUB,3,FALSE),"") | E49: =IFERROR(VLOOKUP(C49,TBL_SUB,5,FALSE),"")

Sheet Clientes
A1: 👤 CLIENTES
A2: Maestro de clientes con suscripción activa o histórica
A4: ID Cliente | B4: Nombre | C4: Email | D4: Teléfono | E4: Fecha alta | F4: Activo | G4: Notas
A5: CLI-001 | B5: Jhon Amaya | C5: jhon@paranoia.com | D5: +57 300 111 1111 | E5: 46078 | F5: Sí | G5: Cliente desde marzo 2026
A6: CLI-002 | B6: Restfull | C6: ops@restfull.com | D6: +57 300 222 2222 | E6: 46113 | F6: Sí
A7: CLI-003 | B7: Juli Riofrío | C7: juli@avenaza.com | D7: +57 300 333 3333 | E7: 46032 | F7: Sí | G7: Premium
A8: CLI-004 | B8: Jean Aguilar | C8: jean@cortepiedra.co | D8: +57 300 444 4444 | E8: 46130 | F8: Sí | G8: Pago manual
A9: CLI-005 | B9: Avenaza SA | C9: facturacion@avenaza.com | D9: +57 300 555 5555 | E9: 46052 | F9: Sí | G9: Plan anual
A10: CLI-006 | B10: Demo Cliente | C10: demo@mateai.com | D10: +57 300 666 6666 | E10: 46137 | F10: Sí | G10: Trial extendido

Sheet Planes
A1: 📋 PLANES
A2: Catálogo maestro de planes de suscripción
A4: ID Plan | B4: Nombre | C4: Periodicidad | D4: Precio | E4: Puntos por ciclo | F4: Beneficios incluidos | G4: Activo
A5: PLAN-BASIC | B5: Basic | C5: Mensual | D5: 40 | E5: 50 | F5: Soporte estándar · 1 reward/mes | G5: Sí
A6: PLAN-PRO | B6: Pro | C6: Mensual | D6: 80 | E6: 100 | F6: Soporte prioritario · 2 rewards · 5% desc. upsell | G6: Sí
A7: PLAN-ELITE | B7: Elite | C7: Mensual | D7: 150 | E7: 200 | F7: Soporte 24/7 · rewards ilimitados · 10% desc. | G7: Sí
A8: PLAN-ANUAL | B8: Pro Anual | C8: Anual | D8: 800 | E8: 1500 | F8: Plan Pro pagado anual · 2 meses gratis | G8: Sí

Sheet Rewards
A1: 🎁 REWARDS
A2: Catálogo de beneficios canjeables con puntos
A4: ID Reward | B4: Nombre | C4: Tipo | D4: Costo puntos | E4: Plan mínimo | F4: Descripción | G4: Activo
A5: RW-001 | B5: Descuento 10% | C5: Descuento | D5: 100 | E5: PLAN-BASIC | F5: 10% off en próximo upsell | G5: Sí
A6: RW-002 | B6: Descuento 25% | C6: Descuento | D6: 250 | E6: PLAN-PRO | F6: 25% off en próximo upsell | G6: Sí
A7: RW-003 | B7: Mes gratis | C7: Suscripción | D7: 500 | E7: PLAN-PRO | F7: 1 mes gratis al renovar | G7: Sí
A8: RW-004 | B8: Consultoría 30 min | C8: Servicio | D8: 300 | E8: PLAN-PRO | F8: Sesión 1:1 con especialista | G8: Sí
A9: RW-005 | B9: Consultoría 60 min | C9: Servicio | D9: 600 | E9: PLAN-ELITE | F9: Sesión estratégica 60 min | G9: Sí
A10: RW-006 | B10: Acceso early features | C10: Acceso | D10: 150 | E10: PLAN-BASIC | F10: Beta de nuevas funciones | G10: Sí
A11: RW-007 | B11: Branding pack | C11: Producto | D11: 400 | E11: PLAN-PRO | F11: Plantillas de marca exclusivas | G11: Sí
A12: RW-008 | B12: Auditoría completa | C12: Servicio | D12: 1000 | E12: PLAN-ELITE | F12: Auditoría de negocio integral | G12: Sí

Sheet Canjes
A1: 🏆 CANJES
A2: Registro de rewards solicitados/canjeados por cliente
A4: ID Canje | B4: Fecha | C4: ID Cliente | D4: Cliente (auto) | E4: ID Sub | F4: ID Reward | G4: Reward (auto) | H4: Costo puntos (auto) | I4: Origen | J4: Estado
A5: CJ-0001 | B5: 46122 | C5: CLI-001 | D5: =IFERROR(VLOOKUP(C5,TBL_CLIENTES,2,FALSE),"") | E5: SUB-0001 | F5: RW-001 | G5: =IFERROR(VLOOKUP(F5,TBL_REWARDS,2,FALSE),"") | H5: =IFERROR(VLOOKUP(F5,TBL_REWARDS,4,FALSE),"") | I5: Suscripción | J5: Canjeado
A6: CJ-0002 | B6: 46127 | C6: CLI-003 | D6: =IFERROR(VLOOKUP(C6,TBL_CLIENTES,2,FALSE),"") | E6: SUB-0003 | F6: RW-005 | G6: =IFERROR(VLOOKUP(F6,TBL_REWARDS,2,FALSE),"") | H6: =IFERROR(VLOOKUP(F6,TBL_REWARDS,4,FALSE),"") | I6: Suscripción | J6: Canjeado
A7: CJ-0003 | B7: 46134 | C7: CLI-003 | D7: =IFERROR(VLOOKUP(C7,TBL_CLIENTES,2,FALSE),"") | E7: SUB-0003 | F7: RW-007 | G7: =IFERROR(VLOOKUP(F7,TBL_REWARDS,2,FALSE),"") | H7: =IFERROR(VLOOKUP(F7,TBL_REWARDS,4,FALSE),"") | I7: Manual | J7: Canjeado
A8: CJ-0004 | B8: 46140 | C8: CLI-001 | D8: =IFERROR(VLOOKUP(C8,TBL_CLIENTES,2,FALSE),"") | E8: SUB-0001 | F8: RW-006 | G8: =IFERROR(VLOOKUP(F8,TBL_REWARDS,2,FALSE),"") | H8: =IFERROR(VLOOKUP(F8,TBL_REWARDS,4,FALSE),"") | I8: Automático | J8: Pendiente
A9: CJ-0005 | B9: 46143 | C9: CLI-005 | D9: =IFERROR(VLOOKUP(C9,TBL_CLIENTES,2,FALSE),"") | E9: SUB-0005 | F9: RW-002 | G9: =IFERROR(VLOOKUP(F9,TBL_REWARDS,2,FALSE),"") | H9: =IFERROR(VLOOKUP(F9,TBL_REWARDS,4,FALSE),"") | I9: Suscripción | J9: Canjeado
D10: =IFERROR(VLOOKUP(C10,TBL_CLIENTES,2,FALSE),"") | G10: =IFERROR(VLOOKUP(F10,TBL_REWARDS,2,FALSE),"") | H10: =IFERROR(VLOOKUP(F10,TBL_REWARDS,4,FALSE),"")
D11: =IFERROR(VLOOKUP(C11,TBL_CLIENTES,2,FALSE),"") | G11: =IFERROR(VLOOKUP(F11,TBL_REWARDS,2,FALSE),"") | H11: =IFERROR(VLOOKUP(F11,TBL_REWARDS,4,FALSE),"")
D12: =IFERROR(VLOOKUP(C12,TBL_CLIENTES,2,FALSE),"") | G12: =IFERROR(VLOOKUP(F12,TBL_REWARDS,2,FALSE),"") | H12: =IFERROR(VLOOKUP(F12,TBL_REWARDS,4,FALSE),"")
D13: =IFERROR(VLOOKUP(C13,TBL_CLIENTES,2,FALSE),"") | G13: =IFERROR(VLOOKUP(F13,TBL_REWARDS,2,FALSE),"") | H13: =IFERROR(VLOOKUP(F13,TBL_REWARDS,4,FALSE),"")
